Workbook

Sheet Overview
A1: SELF-DIRECTED PRACTICE PROJECT. Employees, clients, rates, hours and billing data are fictional and invented for skills practice. This is not professional payroll, time-entry or billing experience.
A2: Time-Entry and Billing Validation: Practice Project
A3: Validate a large set of time records quickly and accurately in Excel
A5: Scenario | B5: 30 fictional employees record time to 4 fictional client projects and one internal code over two weeks (Mon 2026-09-14 to Fri 2026-09-25). A separate fictional billing export shows what was billed. The workbook checks that time is complete, clean and agrees with billing.
A6: Volume | B6: 328 time-entry rows, 315 billing lines, 30 employees x 10 working days = 300 expected employee-days.
A7: Sheets | B7: Time_Entries (data + check columns), Billing_Data (export + reconciliation columns), Coverage (30 x 10 grid of missing days), Discrepancy_Log, Summary_Checks (one-page summary of the checks), Lists (employees, projects, rate card, approved leave).
A8: Excel features used | B8: Data validation (drop-downs, hour limits, date limits), filters and freeze panes, SUMIFS, COUNTIFS, INDEX/MATCH lookups, SUMPRODUCT, conditional formatting.
A9: Seeded problems | B9: The data was built with known errors (missing days, duplicates, wrong rates, typos, billing mismatches) so each check can be seen working. The expected count is listed next to the result on Summary_Checks.
A10: Colour code | B10: Blue text = typed input or data. Black = formula. Green = lookup from another sheet. Red = flagged exception.
A11: What this is not | B11: Not professional payroll or billing experience, and no real employer or client data. It is a self-directed exercise.

Sheet Time_Entries
A1: SELF-DIRECTED PRACTICE PROJECT. Employees, clients, rates, hours and billing data are fictional and invented for skills practice. This is not professional payroll, time-entry or billing experience.
A2: Time entries | F2: Note: drop-down and limit rules block bad typing. Pasted or imported data bypasses them, which is why the check columns exist.
A4: Entry ID | B4: Employee ID | C4: Employee | D4: Role | E4: Date | F4: Day | G4: Project | H4: Client | I4: Billable? | J4: Hours | K4: Rate entered ($/h) | L4: Contract rate ($/h) | M4: Key (emp|date|project) | N4: Duplicate | O4: Hours check | P4: Weekend | Q4: Project check | R4: Rate check | S4: Billing check | T4: Exceptions | U4: Expected amount ($)
A5: TE-0001 | B5: E001 | C5: =IFERROR(INDEX(Lists!$B$5:$B$34,MATCH(B5,Lists!$A$5:$A$34,0)),"") -> Avery Abbott | D5: =IFERROR(INDEX(Lists!$C$5:$C$34,MATCH(B5,Lists!$A$5:$A$34,0)),"") -> Project Coordinator | E5: 46279 | F5: =TEXT(E5,"ddd") -> Mon | G5: P101 | H5: =IFERROR(INDEX(Lists!$F$5:$F$9,MATCH(G5,Lists!$E$5:$E$9,0)),"") -> Alder Energy (fictional) | I5: =IFERROR(INDEX(Lists!$G$5:$G$9,MATCH(G5,Lists!$E$5:$E$9,0)),"") -> Y | J5: 8 | K5: 78 | L5: =IF(I5<>"Y","",IFERROR(INDEX(Lists!$L$5:$L$20,MATCH(D5&"|"&G5,Lists!$I$5:$I$20,0)),"")) -> 78 | M5: =B5&"|"&TEXT(E5,"yyyymmdd")&"|"&G5 -> E001|20260914|P101 | N5: =IF(COUNTIFS($M$5:M5,M5)>1,"DUPLICATE","") | O5: =IF(OR(J5<=0,J5>12),"HOURS?","") | P5: =IF(WEEKDAY(E5,2)>5,"WEEKEND","") | Q5: =IF(COUNTIF(Lists!$E$5:$E$9,G5)=0,"PROJECT?","") | R5: =IF(AND(I5="Y",L5<>"",K5<>L5),"RATE","") | S5: =IF(AND(I5="Y",N5="",COUNTIF(Billing_Data!$H$5:$H$319,M5)=0),"NOT BILLED","") | T5: =SUMPRODUCT(--(LEN(N5:S5)>0)) -> 0 | U5: =IF(AND(I5="Y",N5="",L5<>""),J5*L5,0) -> 624
A6: TE-0002 | B6: E001 | C6: =IFERROR(INDEX(Lists!$B$5:$B$34,MATCH(B6,Lists!$A$5:$A$34,0)),"") -> Avery Abbott | D6: =IFERROR(INDEX(Lists!$C$5:$C$34,MATCH(B6,Lists!$A$5:$A$34,0)),"") -> Project Coordinator | E6: 46280 | F6: =TEXT(E6,"ddd") -> Tue | G6: P101 | H6: =IFERROR(INDEX(Lists!$F$5:$F$9,MATCH(G6,Lists!$E$5:$E$9,0)),"") -> Alder Energy (fictional) | I6: =IFERROR(INDEX(Lists!$G$5:$G$9,MATCH(G6,Lists!$E$5:$E$9,0)),"") -> Y | J6: 8 | K6: 78 | L6: =IF(I6<>"Y","",IFERROR(INDEX(Lists!$L$5:$L$20,MATCH(D6&"|"&G6,Lists!$I$5:$I$20,0)),"")) -> 78 | M6: =B6&"|"&TEXT(E6,"yyyymmdd")&"|"&G6 -> E001|20260915|P101 | N6: =IF(COUNTIFS($M$5:M6,M6)>1,"DUPLICATE","") | O6: =IF(OR(J6<=0,J6>12),"HOURS?","") | P6: =IF(WEEKDAY(E6,2)>5,"WEEKEND","") | Q6: =IF(COUNTIF(Lists!$E$5:$E$9,G6)=0,"PROJECT?","") | R6: =IF(AND(I6="Y",L6<>"",K6<>L6),"RATE","") | S6: =IF(AND(I6="Y",N6="",COUNTIF(Billing_Data!$H$5:$H$319,M6)=0),"NOT BILLED","") | T6: =SUMPRODUCT(--(LEN(N6:S6)>0)) -> 0 | U6: =IF(AND(I6="Y",N6="",L6<>""),J6*L6,0) -> 624
A7: TE-0003 | B7: E001 | C7: =IFERROR(INDEX(Lists!$B$5:$B$34,MATCH(B7,Lists!$A$5:$A$34,0)),"") -> Avery Abbott | D7: =IFERROR(INDEX(Lists!$C$5:$C$34,MATCH(B7,Lists!$A$5:$A$34,0)),"") -> Project Coordinator | E7: 46281 | F7: =TEXT(E7,"ddd") -> Wed | G7: P101 | H7: =IFERROR(INDEX(Lists!$F$5:$F$9,MATCH(G7,Lists!$E$5:$E$9,0)),"") -> Alder Energy (fictional) | I7: =IFERROR(INDEX(Lists!$G$5:$G$9,MATCH(G7,Lists!$E$5:$E$9,0)),"") -> Y | J7: 8 | K7: 78 | L7: =IF(I7<>"Y","",IFERROR(INDEX(Lists!$L$5:$L$20,MATCH(D7&"|"&G7,Lists!$I$5:$I$20,0)),"")) -> 78 | M7: =B7&"|"&TEXT(E7,"yyyymmdd")&"|"&G7 -> E001|20260916|P101 | N7: =IF(COUNTIFS($M$5:M7,M7)>1,"DUPLICATE","") | O7: =IF(OR(J7<=0,J7>12),"HOURS?","") | P7: =IF(WEEKDAY(E7,2)>5,"WEEKEND","") | Q7: =IF(COUNTIF(Lists!$E$5:$E$9,G7)=0,"PROJECT?","") | R7: =IF(AND(I7="Y",L7<>"",K7<>L7),"RATE","") | S7: =IF(AND(I7="Y",N7="",COUNTIF(Billing_Data!$H$5:$H$319,M7)=0),"NOT BILLED","") | T7: =SUMPRODUCT(--(LEN(N7:S7)>0)) -> 0 | U7: =IF(AND(I7="Y",N7="",L7<>""),J7*L7,0) -> 624
A8: TE-0004 | B8: E001 | C8: =IFERROR(INDEX(Lists!$B$5:$B$34,MATCH(B8,Lists!$A$5:$A$34,0)),"") -> Avery Abbott | D8: =IFERROR(INDEX(Lists!$C$5:$C$34,MATCH(B8,Lists!$A$5:$A$34,0)),"") -> Project Coordinator | E8: 46282 | F8: =TEXT(E8,"ddd") -> Thu | G8: P101 | H8: =IFERROR(INDEX(Lists!$F$5:$F$9,MATCH(G8,Lists!$E$5:$E$9,0)),"") -> Alder Energy (fictional) | I8: =IFERROR(INDEX(Lists!$G$5:$G$9,MATCH(G8,Lists!$E$5:$E$9,0)),"") -> Y | J8: 4 | K8: 78 | L8: =IF(I8<>"Y","",IFERROR(INDEX(Lists!$L$5:$L$20,MATCH(D8&"|"&G8,Lists!$I$5:$I$20,0)),"")) -> 78 | M8: =B8&"|"&TEXT(E8,"yyyymmdd")&"|"&G8 -> E001|20260917|P101 | N8: =IF(COUNTIFS($M$5:M8,M8)>1,"DUPLICATE","") | O8: =IF(OR(J8<=0,J8>12),"HOURS?","") | P8: =IF(WEEKDAY(E8,2)>5,"WEEKEND","") | Q8: =IF(COUNTIF(Lists!$E$5:$E$9,G8)=0,"PROJECT?","") | R8: =IF(AND(I8="Y",L8<>"",K8<>L8),"RATE","") | S8: =IF(AND(I8="Y",N8="",COUNTIF(Billing_Data!$H$5:$H$319,M8)=0),"NOT BILLED","") | T8: =SUMPRODUCT(--(LEN(N8:S8)>0)) -> 0 | U8: =IF(AND(I8="Y",N8="",L8<>""),J8*L8,0) -> 312
A9: TE-0005 | B9: E001 | C9: =IFERROR(INDEX(Lists!$B$5:$B$34,MATCH(B9,Lists!$A$5:$A$34,0)),"") -> Avery Abbott | D9: =IFERROR(INDEX(Lists!$C$5:$C$34,MATCH(B9,Lists!$A$5:$A$34,0)),"") -> Project Coordinator | E9: 46282 | F9: =TEXT(E9,"ddd") -> Thu | G9: P102 | H9: =IFERROR(INDEX(Lists!$F$5:$F$9,MATCH(G9,Lists!$E$5:$E$9,0)),"") -> Birchwood Midstream (fictional) | I9: =IFERROR(INDEX(Lists!$G$5:$G$9,MATCH(G9,Lists!$E$5:$E$9,0)),"") -> Y | J9: 4 | K9: 82 | L9: =IF(I9<>"Y","",IFERROR(INDEX(Lists!$L$5:$L$20,MATCH(D9&"|"&G9,Lists!$I$5:$I$20,0)),"")) -> 82 | M9: =B9&"|"&TEXT(E9,"yyyymmdd")&"|"&G9 -> E001|20260917|P102 | N9: =IF(COUNTIFS($M$5:M9,M9)>1,"DUPLICATE","") | O9: =IF(OR(J9<=0,J9>12),"HOURS?","") | P9: =IF(WEEKDAY(E9,2)>5,"WEEKEND","") | Q9: =IF(COUNTIF(Lists!$E$5:$E$9,G9)=0,"PROJECT?","") | R9: =IF(AND(I9="Y",L9<>"",K9<>L9),"RATE","") | S9: =IF(AND(I9="Y",N9="",COUNTIF(Billing_Data!$H$5:$H$319,M9)=0),"NOT BILLED","") | T9: =SUMPRODUCT(--(LEN(N9:S9)>0)) -> 0 | U9: =IF(AND(I9="Y",N9="",L9<>""),J9*L9,0) -> 328
A10: TE-0006 | B10: E001 | C10: =IFERROR(INDEX(Lists!$B$5:$B$34,MATCH(B10,Lists!$A$5:$A$34,0)),"") -> Avery Abbott | D10: =IFERROR(INDEX(Lists!$C$5:$C$34,MATCH(B10,Lists!$A$5:$A$34,0)),"") -> Project Coordinator | E10: 46283 | F10: =TEXT(E10,"ddd") -> Fri | G10: P101 | H10: =IFERROR(INDEX(Lists!$F$5:$F$9,MATCH(G10,Lists!$E$5:$E$9,0)),"") -> Alder Energy (fictional) | I10: =IFERROR(INDEX(Lists!$G$5:$G$9,MATCH(G10,Lists!$E$5:$E$9,0)),"") -> Y | J10: 8 | K10: 78 | L10: =IF(I10<>"Y","",IFERROR(INDEX(Lists!$L$5:$L$20,MATCH(D10&"|"&G10,Lists!$I$5:$I$20,0)),"")) -> 78 | M10: =B10&"|"&TEXT(E10,"yyyymmdd")&"|"&G10 -> E001|20260918|P101 | N10: =IF(COUNTIFS($M$5:M10,M10)>1,"DUPLICATE","") | O10: =IF(OR(J10<=0,J10>12),"HOURS?","") | P10: =IF(WEEKDAY(E10,2)>5,"WEEKEND","") | Q10: =IF(COUNTIF(Lists!$E$5:$E$9,G10)=0,"PROJECT?","") | R10: =IF(AND(I10="Y",L10<>"",K10<>L10),"RATE","") | S10: =IF(AND(I10="Y",N10="",COUNTIF(Billing_Data!$H$5:$H$319,M10)=0),"NOT BILLED","") | T10: =SUMPRODUCT(--(LEN(N10:S10)>0)) -> 0 | U10: =IF(AND(I10="Y",N10="",L10<>""),J10*L10,0) -> 624
A11: TE-0007 | B11: E001 | C11: =IFERROR(INDEX(Lists!$B$5:$B$34,MATCH(B11,Lists!$A$5:$A$34,0)),"") -> Avery Abbott | D11: =IFERROR(INDEX(Lists!$C$5:$C$34,MATCH(B11,Lists!$A$5:$A$34,0)),"") -> Project Coordinator | E11: 46286 | F11: =TEXT(E11,"ddd") -> Mon | G11: P101 | H11: =IFERROR(INDEX(Lists!$F$5:$F$9,MATCH(G11,Lists!$E$5:$E$9,0)),"") -> Alder Energy (fictional) | I11: =IFERROR(INDEX(Lists!$G$5:$G$9,MATCH(G11,Lists!$E$5:$E$9,0)),"") -> Y | J11: 4 | K11: 78 | L11: =IF(I11<>"Y","",IFERROR(INDEX(Lists!$L$5:$L$20,MATCH(D11&"|"&G11,Lists!$I$5:$I$20,0)),"")) -> 78 | M11: =B11&"|"&TEXT(E11,"yyyymmdd")&"|"&G11 -> E001|20260921|P101 | N11: =IF(COUNTIFS($M$5:M11,M11)>1,"DUPLICATE","") | O11: =IF(OR(J11<=0,J11>12),"HOURS?","") | P11: =IF(WEEKDAY(E11,2)>5,"WEEKEND","") | Q11: =IF(COUNTIF(Lists!$E$5:$E$9,G11)=0,"PROJECT?","") | R11: =IF(AND(I11="Y",L11<>"",K11<>L11),"RATE","") | S11: =IF(AND(I11="Y",N11="",COUNTIF(Billing_Data!$H$5:$H$319,M11)=0),"NOT BILLED","") | T11: =SUMPRODUCT(--(LEN(N11:S11)>0)) -> 0 | U11: =IF(AND(I11="Y",N11="",L11<>""),J11*L11,0) -> 312
A12: TE-0008 | B12: E001 | C12: =IFERROR(INDEX(Lists!$B$5:$B$34,MATCH(B12,Lists!$A$5:$A$34,0)),"") -> Avery Abbott | D12: =IFERROR(INDEX(Lists!$C$5:$C$34,MATCH(B12,Lists!$A$5:$A$34,0)),"") -> Project Coordinator | E12: 46286 | F12: =TEXT(E12,"ddd") -> Mon | G12: P103 | H12: =IFERROR(INDEX(Lists!$F$5:$F$9,MATCH(G12,Lists!$E$5:$E$9,0)),"") -> Cedar Industrial (fictional) | I12: =IFERROR(INDEX(Lists!$G$5:$G$9,MATCH(G12,Lists!$E$5:$E$9,0)),"") -> Y | J12: 4 | K12: 74 | L12: =IF(I12<>"Y","",IFERROR(INDEX(Lists!$L$5:$L$20,MATCH(D12&"|"&G12,Lists!$I$5:$I$20,0)),"")) -> 74 | M12: =B12&"|"&TEXT(E12,"yyyymmdd")&"|"&G12 -> E001|20260921|P103 | N12: =IF(COUNTIFS($M$5:M12,M12)>1,"DUPLICATE","") | O12: =IF(OR(J12<=0,J12>12),"HOURS?","") | P12: =IF(WEEKDAY(E12,2)>5,"WEEKEND","") | Q12: =IF(COUNTIF(Lists!$E$5:$E$9,G12)=0,"PROJECT?","") | R12: =IF(AND(I12="Y",L12<>"",K12<>L12),"RATE","") | S12: =IF(AND(I12="Y",N12="",COUNTIF(Billing_Data!$H$5:$H$319,M12)=0),"NOT BILLED","") | T12: =SUMPRODUCT(--(LEN(N12:S12)>0)) -> 0 | U12: =IF(AND(I12="Y",N12="",L12<>""),J12*L12,0) -> 296
A13: TE-0009 | B13: E001 | C13: =IFERROR(INDEX(Lists!$B$5:$B$34,MATCH(B13,Lists!$A$5:$A$34,0)),"") -> Avery Abbott | D13: =IFERROR(INDEX(Lists!$C$5:$C$34,MATCH(B13,Lists!$A$5:$A$34,0)),"") -> Project Coordinator | E13: 46287 | F13: =TEXT(E13,"ddd") -> Tue | G13: P101 | H13: =IFERROR(INDEX(Lists!$F$5:$F$9,MATCH(G13,Lists!$E$5:$E$9,0)),"") -> Alder Energy (fictional) | I13: =IFERROR(INDEX(Lists!$G$5:$G$9,MATCH(G13,Lists!$E$5:$E$9,0)),"") -> Y | J13: 4 | K13: 78 | L13: =IF(I13<>"Y","",IFERROR(INDEX(Lists!$L$5:$L$20,MATCH(D13&"|"&G13,Lists!$I$5:$I$20,0)),"")) -> 78 | M13: =B13&"|"&TEXT(E13,"yyyymmdd")&"|"&G13 -> E001|20260922|P101 | N13: =IF(COUNTIFS($M$5:M13,M13)>1,"DUPLICATE","") | O13: =IF(OR(J13<=0,J13>12),"HOURS?","") | P13: =IF(WEEKDAY(E13,2)>5,"WEEKEND","") | Q13: =IF(COUNTIF(Lists!$E$5:$E$9,G13)=0,"PROJECT?","") | R13: =IF(AND(I13="Y",L13<>"",K13<>L13),"RATE","") | S13: =IF(AND(I13="Y",N13="",COUNTIF(Billing_Data!$H$5:$H$319,M13)=0),"NOT BILLED","") | T13: =SUMPRODUCT(--(LEN(N13:S13)>0)) -> 0 | U13: =IF(AND(I13="Y",N13="",L13<>""),J13*L13,0) -> 312
A14: TE-0010 | B14: E001 | C14: =IFERROR(INDEX(Lists!$B$5:$B$34,MATCH(B14,Lists!$A$5:$A$34,0)),"") -> Avery Abbott | D14: =IFERROR(INDEX(Lists!$C$5:$C$34,MATCH(B14,Lists!$A$5:$A$34,0)),"") -> Project Coordinator | E14: 46287 | F14: =TEXT(E14,"ddd") -> Tue | G14: INT-001 | H14: =IFERROR(INDEX(Lists!$F$5:$F$9,MATCH(G14,Lists!$E$5:$E$9,0)),"") -> Internal / non-billable | I14: =IFERROR(INDEX(Lists!$G$5:$G$9,MATCH(G14,Lists!$E$5:$E$9,0)),"") -> N | J14: 4 | K14: 0 | L14: =IF(I14<>"Y","",IFERROR(INDEX(Lists!$L$5:$L$20,MATCH(D14&"|"&G14,Lists!$I$5:$I$20,0)),"")) | M14: =B14&"|"&TEXT(E14,"yyyymmdd")&"|"&G14 -> E001|20260922|INT-001 | N14: =IF(COUNTIFS($M$5:M14,M14)>1,"DUPLICATE","") | O14: =IF(OR(J14<=0,J14>12),"HOURS?","") | P14: =IF(WEEKDAY(E14,2)>5,"WEEKEND","") | Q14: =IF(COUNTIF(Lists!$E$5:$E$9,G14)=0,"PROJECT?","") | R14: =IF(AND(I14="Y",L14<>"",K14<>L14),"RATE","") | S14: =IF(AND(I14="Y",N14="",COUNTIF(Billing_Data!$H$5:$H$319,M14)=0),"NOT BILLED","") | T14: =SUMPRODUCT(--(LEN(N14:S14)>0)) -> 0 | U14: =IF(AND(I14="Y",N14="",L14<>""),J14*L14,0) -> 0
A15: TE-0011 | B15: E001 | C15: =IFERROR(INDEX(Lists!$B$5:$B$34,MATCH(B15,Lists!$A$5:$A$34,0)),"") -> Avery Abbott | D15: =IFERROR(INDEX(Lists!$C$5:$C$34,MATCH(B15,Lists!$A$5:$A$34,0)),"") -> Project Coordinator | E15: 46288 | F15: =TEXT(E15,"ddd") -> Wed | G15: P101 | H15: =IFERROR(INDEX(Lists!$F$5:$F$9,MATCH(G15,Lists!$E$5:$E$9,0)),"") -> Alder Energy (fictional) | I15: =IFERROR(INDEX(Lists!$G$5:$G$9,MATCH(G15,Lists!$E$5:$E$9,0)),"") -> Y | J15: 8 | K15: 78 | L15: =IF(I15<>"Y","",IFERROR(INDEX(Lists!$L$5:$L$20,MATCH(D15&"|"&G15,Lists!$I$5:$I$20,0)),"")) -> 78 | M15: =B15&"|"&TEXT(E15,"yyyymmdd")&"|"&G15 -> E001|20260923|P101 | N15: =IF(COUNTIFS($M$5:M15,M15)>1,"DUPLICATE","") | O15: =IF(OR(J15<=0,J15>12),"HOURS?","") | P15: =IF(WEEKDAY(E15,2)>5,"WEEKEND","") | Q15: =IF(COUNTIF(Lists!$E$5:$E$9,G15)=0,"PROJECT?","") | R15: =IF(AND(I15="Y",L15<>"",K15<>L15),"RATE","") | S15: =IF(AND(I15="Y",N15="",COUNTIF(Billing_Data!$H$5:$H$319,M15)=0),"NOT BILLED","") | T15: =SUMPRODUCT(--(LEN(N15:S15)>0)) -> 0 | U15: =IF(AND(I15="Y",N15="",L15<>""),J15*L15,0) -> 624
A16: TE-0012 | B16: E001 | C16: =IFERROR(INDEX(Lists!$B$5:$B$34,MATCH(B16,Lists!$A$5:$A$34,0)),"") -> Avery Abbott | D16: =IFERROR(INDEX(Lists!$C$5:$C$34,MATCH(B16,Lists!$A$5:$A$34,0)),"") -> Project Coordinator | E16: 46289 | F16: =TEXT(E16,"ddd") -> Thu | G16: P101 | H16: =IFERROR(INDEX(Lists!$F$5:$F$9,MATCH(G16,Lists!$E$5:$E$9,0)),"") -> Alder Energy (fictional) | I16: =IFERROR(INDEX(Lists!$G$5:$G$9,MATCH(G16,Lists!$E$5:$E$9,0)),"") -> Y | J16: 8 | K16: 78 | L16: =IF(I16<>"Y","",IFERROR(INDEX(Lists!$L$5:$L$20,MATCH(D16&"|"&G16,Lists!$I$5:$I$20,0)),"")) -> 78 | M16: =B16&"|"&TEXT(E16,"yyyymmdd")&"|"&G16 -> E001|20260924|P101 | N16: =IF(COUNTIFS($M$5:M16,M16)>1,"DUPLICATE","") | O16: =IF(OR(J16<=0,J16>12),"HOURS?","") | P16: =IF(WEEKDAY(E16,2)>5,"WEEKEND","") | Q16: =IF(COUNTIF(Lists!$E$5:$E$9,G16)=0,"PROJECT?","") | R16: =IF(AND(I16="Y",L16<>"",K16<>L16),"RATE","") | S16: =IF(AND(I16="Y",N16="",COUNTIF(Billing_Data!$H$5:$H$319,M16)=0),"NOT BILLED","") | T16: =SUMPRODUCT(--(LEN(N16:S16)>0)) -> 0 | U16: =IF(AND(I16="Y",N16="",L16<>""),J16*L16,0) -> 624
... A332: TE-0328 | B332: E022 | C332: =IFERROR(INDEX(Lists!$B$5:$B$34,MATCH(B332,Lists!$A$5:$A$34,0)),"") -> Drew Vance | D332: =IFERROR(INDEX(Lists!$C$5:$C$34,MATCH(B332,Lists!$A$5:$A$34,0)),"") -> Field Supervisor | E332: 46281 | F332: =TEXT(E332,"ddd") -> Wed | G332: P102 | H332: =IFERROR(INDEX(Lists!$F$5:$F$9,MATCH(G332,Lists!$E$5:$E$9,0)),"") -> Birchwood Midstream (fictional) | I332: =IFERROR(INDEX(Lists!$G$5:$G$9,MATCH(G332,Lists!$E$5:$E$9,0)),"") -> Y | J332: 8 | K332: 124 | L332: =IF(I332<>"Y","",IFERROR(INDEX(Lists!$L$5:$L$20,MATCH(D332&"|"&G332,Lists!$I$5:$I$20,0)),"")) -> 124 | M332: =B332&"|"&TEXT(E332,"yyyymmdd")&"|"&G332 -> E022|20260916|P102 | N332: =IF(COUNTIFS($M$5:M332,M332)>1,"DUPLICATE","") -> DUPLICATE | O332: =IF(OR(J332<=0,J332>12),"HOURS?","") | P332: =IF(WEEKDAY(E332,2)>5,"WEEKEND","") | Q332: =IF(COUNTIF(Lists!$E$5:$E$9,G332)=0,"PROJECT?","") | R332: =IF(AND(I332="Y",L332<>"",K332<>L332),"RATE","") | S332: =IF(AND(I332="Y",N332="",COUNTIF(Billing_Data!$H$5:$H$319,M332)=0),"NOT BILLED","") | T332: =SUMPRODUCT(--(LEN(N332:S332)>0)) -> 1 | U332: =IF(AND(I332="Y",N332="",L332<>""),J332*L332,0) -> 0

Sheet Billing_Data
A1: SELF-DIRECTED PRACTICE PROJECT. Employees, clients, rates, hours and billing data are fictional and invented for skills practice. This is not professional payroll, time-entry or billing experience.
A2: Billing export and reconciliation to time entries
A4: Billing line | B4: Employee ID | C4: Date | D4: Project | E4: Hours billed | F4: Rate billed ($/h) | G4: Amount billed ($) | H4: Key (emp|date|project) | I4: Time entered, excl. duplicates (h) | J4: Hours difference | K4: Contract rate ($/h) | L4: Rate difference | M4: Expected amount ($) | N4: Amount variance ($) | O4: Status
A5: BL-0001 | B5: E001 | C5: 46279 | D5: P101 | E5: 8 | F5: 78 | G5: 624 | H5: =B5&"|"&TEXT(C5,"yyyymmdd")&"|"&D5 -> E001|20260914|P101 | I5: =SUMIFS(Time_Entries!$J$5:$J$332,Time_Entries!$M$5:$M$332,H5,Time_Entries!$N$5:$N$332,"") -> 8 | J5: =E5-I5 -> 0 | K5: =IFERROR(INDEX(Lists!$L$5:$L$20,MATCH(INDEX(Lists!$C$5:$C$34,MATCH(B5,Lists!$A$5:$A$34,0))&"|"&D5,Lists!$I$5:$I$20,0)),"") -> 78 | L5: =IF(K5="","",F5-K5) -> 0 | M5: =IF(K5="",0,I5*K5) -> 624 | N5: =G5-M5 -> 0 | O5: =IF(I5=0,"NO TIME ENTRY",IF(ABS(J5)>0.001,"HOURS",IF(AND(K5<>"",ABS(L5)>0.001),"RATE","OK"))) -> OK
A6: BL-0002 | B6: E002 | C6: 46279 | D6: P101 | E6: 4 | F6: 78 | G6: 312 | H6: =B6&"|"&TEXT(C6,"yyyymmdd")&"|"&D6 -> E002|20260914|P101 | I6: =SUMIFS(Time_Entries!$J$5:$J$332,Time_Entries!$M$5:$M$332,H6,Time_Entries!$N$5:$N$332,"") -> 4 | J6: =E6-I6 -> 0 | K6: =IFERROR(INDEX(Lists!$L$5:$L$20,MATCH(INDEX(Lists!$C$5:$C$34,MATCH(B6,Lists!$A$5:$A$34,0))&"|"&D6,Lists!$I$5:$I$20,0)),"") -> 78 | L6: =IF(K6="","",F6-K6) -> 0 | M6: =IF(K6="",0,I6*K6) -> 312 | N6: =G6-M6 -> 0 | O6: =IF(I6=0,"NO TIME ENTRY",IF(ABS(J6)>0.001,"HOURS",IF(AND(K6<>"",ABS(L6)>0.001),"RATE","OK"))) -> OK
A7: BL-0003 | B7: E002 | C7: 46279 | D7: P102 | E7: 4 | F7: 82 | G7: 328 | H7: =B7&"|"&TEXT(C7,"yyyymmdd")&"|"&D7 -> E002|20260914|P102 | I7: =SUMIFS(Time_Entries!$J$5:$J$332,Time_Entries!$M$5:$M$332,H7,Time_Entries!$N$5:$N$332,"") -> 4 | J7: =E7-I7 -> 0 | K7: =IFERROR(INDEX(Lists!$L$5:$L$20,MATCH(INDEX(Lists!$C$5:$C$34,MATCH(B7,Lists!$A$5:$A$34,0))&"|"&D7,Lists!$I$5:$I$20,0)),"") -> 82 | L7: =IF(K7="","",F7-K7) -> 0 | M7: =IF(K7="",0,I7*K7) -> 328 | N7: =G7-M7 -> 0 | O7: =IF(I7=0,"NO TIME ENTRY",IF(ABS(J7)>0.001,"HOURS",IF(AND(K7<>"",ABS(L7)>0.001),"RATE","OK"))) -> OK
A8: BL-0004 | B8: E003 | C8: 46279 | D8: P103 | E8: 4 | F8: 74 | G8: 296 | H8: =B8&"|"&TEXT(C8,"yyyymmdd")&"|"&D8 -> E003|20260914|P103 | I8: =SUMIFS(Time_Entries!$J$5:$J$332,Time_Entries!$M$5:$M$332,H8,Time_Entries!$N$5:$N$332,"") -> 4 | J8: =E8-I8 -> 0 | K8: =IFERROR(INDEX(Lists!$L$5:$L$20,MATCH(INDEX(Lists!$C$5:$C$34,MATCH(B8,Lists!$A$5:$A$34,0))&"|"&D8,Lists!$I$5:$I$20,0)),"") -> 74 | L8: =IF(K8="","",F8-K8) -> 0 | M8: =IF(K8="",0,I8*K8) -> 296 | N8: =G8-M8 -> 0 | O8: =IF(I8=0,"NO TIME ENTRY",IF(ABS(J8)>0.001,"HOURS",IF(AND(K8<>"",ABS(L8)>0.001),"RATE","OK"))) -> OK
A9: BL-0005 | B9: E003 | C9: 46279 | D9: P104 | E9: 4 | F9: 86 | G9: 344 | H9: =B9&"|"&TEXT(C9,"yyyymmdd")&"|"&D9 -> E003|20260914|P104 | I9: =SUMIFS(Time_Entries!$J$5:$J$332,Time_Entries!$M$5:$M$332,H9,Time_Entries!$N$5:$N$332,"") -> 4 | J9: =E9-I9 -> 0 | K9: =IFERROR(INDEX(Lists!$L$5:$L$20,MATCH(INDEX(Lists!$C$5:$C$34,MATCH(B9,Lists!$A$5:$A$34,0))&"|"&D9,Lists!$I$5:$I$20,0)),"") -> 86 | L9: =IF(K9="","",F9-K9) -> 0 | M9: =IF(K9="",0,I9*K9) -> 344 | N9: =G9-M9 -> 0 | O9: =IF(I9=0,"NO TIME ENTRY",IF(ABS(J9)>0.001,"HOURS",IF(AND(K9<>"",ABS(L9)>0.001),"RATE","OK"))) -> OK
A10: BL-0006 | B10: E004 | C10: 46279 | D10: P104 | E10: 8 | F10: 86 | G10: 688 | H10: =B10&"|"&TEXT(C10,"yyyymmdd")&"|"&D10 -> E004|20260914|P104 | I10: =SUMIFS(Time_Entries!$J$5:$J$332,Time_Entries!$M$5:$M$332,H10,Time_Entries!$N$5:$N$332,"") -> 8 | J10: =E10-I10 -> 0 | K10: =IFERROR(INDEX(Lists!$L$5:$L$20,MATCH(INDEX(Lists!$C$5:$C$34,MATCH(B10,Lists!$A$5:$A$34,0))&"|"&D10,Lists!$I$5:$I$20,0)),"") -> 86 | L10: =IF(K10="","",F10-K10) -> 0 | M10: =IF(K10="",0,I10*K10) -> 688 | N10: =G10-M10 -> 0 | O10: =IF(I10=0,"NO TIME ENTRY",IF(ABS(J10)>0.001,"HOURS",IF(AND(K10<>"",ABS(L10)>0.001),"RATE","OK"))) -> OK
A11: BL-0007 | B11: E005 | C11: 46279 | D11: P101 | E11: 8 | F11: 78 | G11: 624 | H11: =B11&"|"&TEXT(C11,"yyyymmdd")&"|"&D11 -> E005|20260914|P101 | I11: =SUMIFS(Time_Entries!$J$5:$J$332,Time_Entries!$M$5:$M$332,H11,Time_Entries!$N$5:$N$332,"") -> 8 | J11: =E11-I11 -> 0 | K11: =IFERROR(INDEX(Lists!$L$5:$L$20,MATCH(INDEX(Lists!$C$5:$C$34,MATCH(B11,Lists!$A$5:$A$34,0))&"|"&D11,Lists!$I$5:$I$20,0)),"") -> 78 | L11: =IF(K11="","",F11-K11) -> 0 | M11: =IF(K11="",0,I11*K11) -> 624 | N11: =G11-M11 -> 0 | O11: =IF(I11=0,"NO TIME ENTRY",IF(ABS(J11)>0.001,"HOURS",IF(AND(K11<>"",ABS(L11)>0.001),"RATE","OK"))) -> OK
A12: BL-0008 | B12: E006 | C12: 46279 | D12: P102 | E12: 4 | F12: 82 | G12: 328 | H12: =B12&"|"&TEXT(C12,"yyyymmdd")&"|"&D12 -> E006|20260914|P102 | I12: =SUMIFS(Time_Entries!$J$5:$J$332,Time_Entries!$M$5:$M$332,H12,Time_Entries!$N$5:$N$332,"") -> 4 | J12: =E12-I12 -> 0 | K12: =IFERROR(INDEX(Lists!$L$5:$L$20,MATCH(INDEX(Lists!$C$5:$C$34,MATCH(B12,Lists!$A$5:$A$34,0))&"|"&D12,Lists!$I$5:$I$20,0)),"") -> 82 | L12: =IF(K12="","",F12-K12) -> 0 | M12: =IF(K12="",0,I12*K12) -> 328 | N12: =G12-M12 -> 0 | O12: =IF(I12=0,"NO TIME ENTRY",IF(ABS(J12)>0.001,"HOURS",IF(AND(K12<>"",ABS(L12)>0.001),"RATE","OK"))) -> OK
A13: BL-0009 | B13: E006 | C13: 46279 | D13: P104 | E13: 4 | F13: 86 | G13: 344 | H13: =B13&"|"&TEXT(C13,"yyyymmdd")&"|"&D13 -> E006|20260914|P104 | I13: =SUMIFS(Time_Entries!$J$5:$J$332,Time_Entries!$M$5:$M$332,H13,Time_Entries!$N$5:$N$332,"") -> 4 | J13: =E13-I13 -> 0 | K13: =IFERROR(INDEX(Lists!$L$5:$L$20,MATCH(INDEX(Lists!$C$5:$C$34,MATCH(B13,Lists!$A$5:$A$34,0))&"|"&D13,Lists!$I$5:$I$20,0)),"") -> 86 | L13: =IF(K13="","",F13-K13) -> 0 | M13: =IF(K13="",0,I13*K13) -> 344 | N13: =G13-M13 -> 0 | O13: =IF(I13=0,"NO TIME ENTRY",IF(ABS(J13)>0.001,"HOURS",IF(AND(K13<>"",ABS(L13)>0.001),"RATE","OK"))) -> OK
A14: BL-0010 | B14: E007 | C14: 46279 | D14: P103 | E14: 8 | F14: 74 | G14: 592 | H14: =B14&"|"&TEXT(C14,"yyyymmdd")&"|"&D14 -> E007|20260914|P103 | I14: =SUMIFS(Time_Entries!$J$5:$J$332,Time_Entries!$M$5:$M$332,H14,Time_Entries!$N$5:$N$332,"") -> 8 | J14: =E14-I14 -> 0 | K14: =IFERROR(INDEX(Lists!$L$5:$L$20,MATCH(INDEX(Lists!$C$5:$C$34,MATCH(B14,Lists!$A$5:$A$34,0))&"|"&D14,Lists!$I$5:$I$20,0)),"") -> 74 | L14: =IF(K14="","",F14-K14) -> 0 | M14: =IF(K14="",0,I14*K14) -> 592 | N14: =G14-M14 -> 0 | O14: =IF(I14=0,"NO TIME ENTRY",IF(ABS(J14)>0.001,"HOURS",IF(AND(K14<>"",ABS(L14)>0.001),"RATE","OK"))) -> OK
A15: BL-0011 | B15: E008 | C15: 46279 | D15: P104 | E15: 8 | F15: 86 | G15: 688 | H15: =B15&"|"&TEXT(C15,"yyyymmdd")&"|"&D15 -> E008|20260914|P104 | I15: =SUMIFS(Time_Entries!$J$5:$J$332,Time_Entries!$M$5:$M$332,H15,Time_Entries!$N$5:$N$332,"") -> 8 | J15: =E15-I15 -> 0 | K15: =IFERROR(INDEX(Lists!$L$5:$L$20,MATCH(INDEX(Lists!$C$5:$C$34,MATCH(B15,Lists!$A$5:$A$34,0))&"|"&D15,Lists!$I$5:$I$20,0)),"") -> 86 | L15: =IF(K15="","",F15-K15) -> 0 | M15: =IF(K15="",0,I15*K15) -> 688 | N15: =G15-M15 -> 0 | O15: =IF(I15=0,"NO TIME ENTRY",IF(ABS(J15)>0.001,"HOURS",IF(AND(K15<>"",ABS(L15)>0.001),"RATE","OK"))) -> OK
A16: BL-0012 | B16: E009 | C16: 46279 | D16: P101 | E16: 8 | F16: 78 | G16: 624 | H16: =B16&"|"&TEXT(C16,"yyyymmdd")&"|"&D16 -> E009|20260914|P101 | I16: =SUMIFS(Time_Entries!$J$5:$J$332,Time_Entries!$M$5:$M$332,H16,Time_Entries!$N$5:$N$332,"") -> 8 | J16: =E16-I16 -> 0 | K16: =IFERROR(INDEX(Lists!$L$5:$L$20,MATCH(INDEX(Lists!$C$5:$C$34,MATCH(B16,Lists!$A$5:$A$34,0))&"|"&D16,Lists!$I$5:$I$20,0)),"") -> 78 | L16: =IF(K16="","",F16-K16) -> 0 | M16: =IF(K16="",0,I16*K16) -> 624 | N16: =G16-M16 -> 0 | O16: =IF(I16=0,"NO TIME ENTRY",IF(ABS(J16)>0.001,"HOURS",IF(AND(K16<>"",ABS(L16)>0.001),"RATE","OK"))) -> OK
... A319: BL-0315 | B319: E030 | C319: 46290 | D319: P104 | E319: 4 | F319: 108 | G319: 432 | H319: =B319&"|"&TEXT(C319,"yyyymmdd")&"|"&D319 -> E030|20260925|P104 | I319: =SUMIFS(Time_Entries!$J$5:$J$332,Time_Entries!$M$5:$M$332,H319,Time_Entries!$N$5:$N$332,"") -> 4 | J319: =E319-I319 -> 0 | K319: =IFERROR(INDEX(Lists!$L$5:$L$20,MATCH(INDEX(Lists!$C$5:$C$34,MATCH(B319,Lists!$A$5:$A$34,0))&"|"&D319,Lists!$I$5:$I$20,0)),"") -> 108 | L319: =IF(K319="","",F319-K319) -> 0 | M319: =IF(K319="",0,I319*K319) -> 432 | N319: =G319-M319 -> 0 | O319: =IF(I319=0,"NO TIME ENTRY",IF(ABS(J319)>0.001,"HOURS",IF(AND(K319<>"",ABS(L319)>0.001),"RATE","OK"))) -> OK

Sheet Coverage
A1: SELF-DIRECTED PRACTICE PROJECT. Employees, clients, rates, hours and billing data are fictional and invented for skills practice. This is not professional payroll, time-entry or billing experience.
A2: Coverage: every employee, every working day
A3: MISSING = no time entry and no approved leave. LEAVE = approved leave. Numbers are hours (duplicates excluded). Amber = not 8 hours.
A5: Employee ID | B5: Employee | C5: 46279 | D5: 46280 | E5: 46281 | F5: 46282 | G5: 46283 | H5: 46286 | I5: 46287 | J5: 46288 | K5: 46289 | L5: 46290 | M5: Total hours | N5: Expected hours | O5: Variance
A6: E001 | B6: =Lists!B5 -> Avery Abbott | C6: =IF(COUNTIFS(Lists!$N$5:$N$7,$A6,Lists!$O$5:$O$7,C$5)>0,"LEAVE",IF(SUMIFS(Time_Entries!$J$5:$J$332,Time_Entries!$B$5:$B$332,$A6,Time_Entries!$E$5:$E$332,C$5,Time_Entries!$N$5:$N$332,"")=0,"MISSING",SUMIFS(Time_Entries!$J$5:$J$332,Time_Entries!$B$5:$B$332,$A6,Time_Entries!$E$5:$E$332,C$5,Time_Entries!$N$5:$N$332,""))) -> 8 | D6: =IF(COUNTIFS(Lists!$N$5:$N$7,$A6,Lists!$O$5:$O$7,D$5)>0,"LEAVE",IF(SUMIFS(Time_Entries!$J$5:$J$332,Time_Entries!$B$5:$B$332,$A6,Time_Entries!$E$5:$E$332,D$5,Time_Entries!$N$5:$N$332,"")=0,"MISSING",SUMIFS(Time_Entries!$J$5:$J$332,Time_Entries!$B$5:$B$332,$A6,Time_Entries!$E$5:$E$332,D$5,Time_Entries!$N$5:$N$332,""))) -> 8 | E6: =IF(COUNTIFS(Lists!$N$5:$N$7,$A6,Lists!$O$5:$O$7,E$5)>0,"LEAVE",IF(SUMIFS(Time_Entries!$J$5:$J$332,Time_Entries!$B$5:$B$332,$A6,Time_Entries!$E$5:$E$332,E$5,Time_Entries!$N$5:$N$332,"")=0,"MISSING",SUMIFS(Time_Entries!$J$5:$J$332,Time_Entries!$B$5:$B$332,$A6,Time_Entries!$E$5:$E$332,E$5,Time_Entries!$N$5:$N$332,""))) -> 8 | F6: =IF(COUNTIFS(Lists!$N$5:$N$7,$A6,Lists!$O$5:$O$7,F$5)>0,"LEAVE",IF(SUMIFS(Time_Entries!$J$5:$J$332,Time_Entries!$B$5:$B$332,$A6,Time_Entries!$E$5:$E$332,F$5,Time_Entries!$N$5:$N$332,"")=0,"MISSING",SUMIFS(Time_Entries!$J$5:$J$332,Time_Entries!$B$5:$B$332,$A6,Time_Entries!$E$5:$E$332,F$5,Time_Entries!$N$5:$N$332,""))) -> 8 | G6: =IF(COUNTIFS(Lists!$N$5:$N$7,$A6,Lists!$O$5:$O$7,G$5)>0,"LEAVE",IF(SUMIFS(Time_Entries!$J$5:$J$332,Time_Entries!$B$5:$B$332,$A6,Time_Entries!$E$5:$E$332,G$5,Time_Entries!$N$5:$N$332,"")=0,"MISSING",SUMIFS(Time_Entries!$J$5:$J$332,Time_Entries!$B$5:$B$332,$A6,Time_Entries!$E$5:$E$332,G$5,Time_Entries!$N$5:$N$332,""))) -> 8 | H6: =IF(COUNTIFS(Lists!$N$5:$N$7,$A6,Lists!$O$5:$O$7,H$5)>0,"LEAVE",IF(SUMIFS(Time_Entries!$J$5:$J$332,Time_Entries!$B$5:$B$332,$A6,Time_Entries!$E$5:$E$332,H$5,Time_Entries!$N$5:$N$332,"")=0,"MISSING",SUMIFS(Time_Entries!$J$5:$J$332,Time_Entries!$B$5:$B$332,$A6,Time_Entries!$E$5:$E$332,H$5,Time_Entries!$N$5:$N$332,""))) -> 8 | I6: =IF(COUNTIFS(Lists!$N$5:$N$7,$A6,Lists!$O$5:$O$7,I$5)>0,"LEAVE",IF(SUMIFS(Time_Entries!$J$5:$J$332,Time_Entries!$B$5:$B$332,$A6,Time_Entries!$E$5:$E$332,I$5,Time_Entries!$N$5:$N$332,"")=0,"MISSING",SUMIFS(Time_Entries!$J$5:$J$332,Time_Entries!$B$5:$B$332,$A6,Time_Entries!$E$5:$E$332,I$5,Time_Entries!$N$5:$N$332,""))) -> 8 | J6: =IF(COUNTIFS(Lists!$N$5:$N$7,$A6,Lists!$O$5:$O$7,J$5)>0,"LEAVE",IF(SUMIFS(Time_Entries!$J$5:$J$332,Time_Entries!$B$5:$B$332,$A6,Time_Entries!$E$5:$E$332,J$5,Time_Entries!$N$5:$N$332,"")=0,"MISSING",SUMIFS(Time_Entries!$J$5:$J$332,Time_Entries!$B$5:$B$332,$A6,Time_Entries!$E$5:$E$332,J$5,Time_Entries!$N$5:$N$332,""))) -> 8 | ... L6: =IF(COUNTIFS(Lists!$N$5:$N$7,$A6,Lists!$O$5:$O$7,L$5)>0,"LEAVE",IF(SUMIFS(Time_Entries!$J$5:$J$332,Time_Entries!$B$5:$B$332,$A6,Time_Entries!$E$5:$E$332,L$5,Time_Entries!$N$5:$N$332,"")=0,"MISSING",SUMIFS(Time_Entries!$J$5:$J$332,Time_Entries!$B$5:$B$332,$A6,Time_Entries!$E$5:$E$332,L$5,Time_Entries!$N$5:$N$332,""))) -> 8 | M6: =SUM(C6:L6) -> 80 | N6: =8*(10-COUNTIF(C6:L6,"LEAVE")) -> 80 | O6: =M6-N6 -> 0
A7: E002 | B7: =Lists!B6 -> Jordan Brennan | C7: =IF(COUNTIFS(Lists!$N$5:$N$7,$A7,Lists!$O$5:$O$7,C$5)>0,"LEAVE",IF(SUMIFS(Time_Entries!$J$5:$J$332,Time_Entries!$B$5:$B$332,$A7,Time_Entries!$E$5:$E$332,C$5,Time_Entries!$N$5:$N$332,"")=0,"MISSING",SUMIFS(Time_Entries!$J$5:$J$332,Time_Entries!$B$5:$B$332,$A7,Time_Entries!$E$5:$E$332,C$5,Time_Entries!$N$5:$N$332,""))) -> 8 | D7: =IF(COUNTIFS(Lists!$N$5:$N$7,$A7,Lists!$O$5:$O$7,D$5)>0,"LEAVE",IF(SUMIFS(Time_Entries!$J$5:$J$332,Time_Entries!$B$5:$B$332,$A7,Time_Entries!$E$5:$E$332,D$5,Time_Entries!$N$5:$N$332,"")=0,"MISSING",SUMIFS(Time_Entries!$J$5:$J$332,Time_Entries!$B$5:$B$332,$A7,Time_Entries!$E$5:$E$332,D$5,Time_Entries!$N$5:$N$332,""))) -> MISSING | E7: =IF(COUNTIFS(Lists!$N$5:$N$7,$A7,Lists!$O$5:$O$7,E$5)>0,"LEAVE",IF(SUMIFS(Time_Entries!$J$5:$J$332,Time_Entries!$B$5:$B$332,$A7,Time_Entries!$E$5:$E$332,E$5,Time_Entries!$N$5:$N$332,"")=0,"MISSING",SUMIFS(Time_Entries!$J$5:$J$332,Time_Entries!$B$5:$B$332,$A7,Time_Entries!$E$5:$E$332,E$5,Time_Entries!$N$5:$N$332,""))) -> 8 | F7: =IF(COUNTIFS(Lists!$N$5:$N$7,$A7,Lists!$O$5:$O$7,F$5)>0,"LEAVE",IF(SUMIFS(Time_Entries!$J$5:$J$332,Time_Entries!$B$5:$B$332,$A7,Time_Entries!$E$5:$E$332,F$5,Time_Entries!$N$5:$N$332,"")=0,"MISSING",SUMIFS(Time_Entries!$J$5:$J$332,Time_Entries!$B$5:$B$332,$A7,Time_Entries!$E$5:$E$332,F$5,Time_Entries!$N$5:$N$332,""))) -> 8 | G7: =IF(COUNTIFS(Lists!$N$5:$N$7,$A7,Lists!$O$5:$O$7,G$5)>0,"LEAVE",IF(SUMIFS(Time_Entries!$J$5:$J$332,Time_Entries!$B$5:$B$332,$A7,Time_Entries!$E$5:$E$332,G$5,Time_Entries!$N$5:$N$332,"")=0,"MISSING",SUMIFS(Time_Entries!$J$5:$J$332,Time_Entries!$B$5:$B$332,$A7,Time_Entries!$E$5:$E$332,G$5,Time_Entries!$N$5:$N$332,""))) -> 8 | H7: =IF(COUNTIFS(Lists!$N$5:$N$7,$A7,Lists!$O$5:$O$7,H$5)>0,"LEAVE",IF(SUMIFS(Time_Entries!$J$5:$J$332,Time_Entries!$B$5:$B$332,$A7,Time_Entries!$E$5:$E$332,H$5,Time_Entries!$N$5:$N$332,"")=0,"MISSING",SUMIFS(Time_Entries!$J$5:$J$332,Time_Entries!$B$5:$B$332,$A7,Time_Entries!$E$5:$E$332,H$5,Time_Entries!$N$5:$N$332,""))) -> 8 | I7: =IF(COUNTIFS(Lists!$N$5:$N$7,$A7,Lists!$O$5:$O$7,I$5)>0,"LEAVE",IF(SUMIFS(Time_Entries!$J$5:$J$332,Time_Entries!$B$5:$B$332,$A7,Time_Entries!$E$5:$E$332,I$5,Time_Entries!$N$5:$N$332,"")=0,"MISSING",SUMIFS(Time_Entries!$J$5:$J$332,Time_Entries!$B$5:$B$332,$A7,Time_Entries!$E$5:$E$332,I$5,Time_Entries!$N$5:$N$332,""))) -> 8 | J7: =IF(COUNTIFS(Lists!$N$5:$N$7,$A7,Lists!$O$5:$O$7,J$5)>0,"LEAVE",IF(SUMIFS(Time_Entries!$J$5:$J$332,Time_Entries!$B$5:$B$332,$A7,Time_Entries!$E$5:$E$332,J$5,Time_Entries!$N$5:$N$332,"")=0,"MISSING",SUMIFS(Time_Entries!$J$5:$J$332,Time_Entries!$B$5:$B$332,$A7,Time_Entries!$E$5:$E$332,J$5,Time_Entries!$N$5:$N$332,""))) -> 8 | ... L7: =IF(COUNTIFS(Lists!$N$5:$N$7,$A7,Lists!$O$5:$O$7,L$5)>0,"LEAVE",IF(SUMIFS(Time_Entries!$J$5:$J$332,Time_Entries!$B$5:$B$332,$A7,Time_Entries!$E$5:$E$332,L$5,Time_Entries!$N$5:$N$332,"")=0,"MISSING",SUMIFS(Time_Entries!$J$5:$J$332,Time_Entries!$B$5:$B$332,$A7,Time_Entries!$E$5:$E$332,L$5,Time_Entries!$N$5:$N$332,""))) -> 8 | M7: =SUM(C7:L7) -> 72 | N7: =8*(10-COUNTIF(C7:L7,"LEAVE")) -> 80 | O7: =M7-N7 -> -8
A8: E003 | B8: =Lists!B7 -> Taylor Calder | C8: =IF(COUNTIFS(Lists!$N$5:$N$7,$A8,Lists!$O$5:$O$7,C$5)>0,"LEAVE",IF(SUMIFS(Time_Entries!$J$5:$J$332,Time_Entries!$B$5:$B$332,$A8,Time_Entries!$E$5:$E$332,C$5,Time_Entries!$N$5:$N$332,"")=0,"MISSING",SUMIFS(Time_Entries!$J$5:$J$332,Time_Entries!$B$5:$B$332,$A8,Time_Entries!$E$5:$E$332,C$5,Time_Entries!$N$5:$N$332,""))) -> 8 | D8: =IF(COUNTIFS(Lists!$N$5:$N$7,$A8,Lists!$O$5:$O$7,D$5)>0,"LEAVE",IF(SUMIFS(Time_Entries!$J$5:$J$332,Time_Entries!$B$5:$B$332,$A8,Time_Entries!$E$5:$E$332,D$5,Time_Entries!$N$5:$N$332,"")=0,"MISSING",SUMIFS(Time_Entries!$J$5:$J$332,Time_Entries!$B$5:$B$332,$A8,Time_Entries!$E$5:$E$332,D$5,Time_Entries!$N$5:$N$332,""))) -> 8 | E8: =IF(COUNTIFS(Lists!$N$5:$N$7,$A8,Lists!$O$5:$O$7,E$5)>0,"LEAVE",IF(SUMIFS(Time_Entries!$J$5:$J$332,Time_Entries!$B$5:$B$332,$A8,Time_Entries!$E$5:$E$332,E$5,Time_Entries!$N$5:$N$332,"")=0,"MISSING",SUMIFS(Time_Entries!$J$5:$J$332,Time_Entries!$B$5:$B$332,$A8,Time_Entries!$E$5:$E$332,E$5,Time_Entries!$N$5:$N$332,""))) -> 8 | F8: =IF(COUNTIFS(Lists!$N$5:$N$7,$A8,Lists!$O$5:$O$7,F$5)>0,"LEAVE",IF(SUMIFS(Time_Entries!$J$5:$J$332,Time_Entries!$B$5:$B$332,$A8,Time_Entries!$E$5:$E$332,F$5,Time_Entries!$N$5:$N$332,"")=0,"MISSING",SUMIFS(Time_Entries!$J$5:$J$332,Time_Entries!$B$5:$B$332,$A8,Time_Entries!$E$5:$E$332,F$5,Time_Entries!$N$5:$N$332,""))) -> 8 | G8: =IF(COUNTIFS(Lists!$N$5:$N$7,$A8,Lists!$O$5:$O$7,G$5)>0,"LEAVE",IF(SUMIFS(Time_Entries!$J$5:$J$332,Time_Entries!$B$5:$B$332,$A8,Time_Entries!$E$5:$E$332,G$5,Time_Entries!$N$5:$N$332,"")=0,"MISSING",SUMIFS(Time_Entries!$J$5:$J$332,Time_Entries!$B$5:$B$332,$A8,Time_Entries!$E$5:$E$332,G$5,Time_Entries!$N$5:$N$332,""))) -> 8 | H8: =IF(COUNTIFS(Lists!$N$5:$N$7,$A8,Lists!$O$5:$O$7,H$5)>0,"LEAVE",IF(SUMIFS(Time_Entries!$J$5:$J$332,Time_Entries!$B$5:$B$332,$A8,Time_Entries!$E$5:$E$332,H$5,Time_Entries!$N$5:$N$332,"")=0,"MISSING",SUMIFS(Time_Entries!$J$5:$J$332,Time_Entries!$B$5:$B$332,$A8,Time_Entries!$E$5:$E$332,H$5,Time_Entries!$N$5:$N$332,""))) -> 8 | I8: =IF(COUNTIFS(Lists!$N$5:$N$7,$A8,Lists!$O$5:$O$7,I$5)>0,"LEAVE",IF(SUMIFS(Time_Entries!$J$5:$J$332,Time_Entries!$B$5:$B$332,$A8,Time_Entries!$E$5:$E$332,I$5,Time_Entries!$N$5:$N$332,"")=0,"MISSING",SUMIFS(Time_Entries!$J$5:$J$332,Time_Entries!$B$5:$B$332,$A8,Time_Entries!$E$5:$E$332,I$5,Time_Entries!$N$5:$N$332,""))) -> 8 | J8: =IF(COUNTIFS(Lists!$N$5:$N$7,$A8,Lists!$O$5:$O$7,J$5)>0,"LEAVE",IF(SUMIFS(Time_Entries!$J$5:$J$332,Time_Entries!$B$5:$B$332,$A8,Time_Entries!$E$5:$E$332,J$5,Time_Entries!$N$5:$N$332,"")=0,"MISSING",SUMIFS(Time_Entries!$J$5:$J$332,Time_Entries!$B$5:$B$332,$A8,Time_Entries!$E$5:$E$332,J$5,Time_Entries!$N$5:$N$332,""))) -> 8 | ... L8: =IF(COUNTIFS(Lists!$N$5:$N$7,$A8,Lists!$O$5:$O$7,L$5)>0,"LEAVE",IF(SUMIFS(Time_Entries!$J$5:$J$332,Time_Entries!$B$5:$B$332,$A8,Time_Entries!$E$5:$E$332,L$5,Time_Entries!$N$5:$N$332,"")=0,"MISSING",SUMIFS(Time_Entries!$J$5:$J$332,Time_Entries!$B$5:$B$332,$A8,Time_Entries!$E$5:$E$332,L$5,Time_Entries!$N$5:$N$332,""))) -> 8 | M8: =SUM(C8:L8) -> 80 | N8: =8*(10-COUNTIF(C8:L8,"LEAVE")) -> 80 | O8: =M8-N8 -> 0
A9: E004 | B9: =Lists!B8 -> Morgan Dalton | C9: =IF(COUNTIFS(Lists!$N$5:$N$7,$A9,Lists!$O$5:$O$7,C$5)>0,"LEAVE",IF(SUMIFS(Time_Entries!$J$5:$J$332,Time_Entries!$B$5:$B$332,$A9,Time_Entries!$E$5:$E$332,C$5,Time_Entries!$N$5:$N$332,"")=0,"MISSING",SUMIFS(Time_Entries!$J$5:$J$332,Time_Entries!$B$5:$B$332,$A9,Time_Entries!$E$5:$E$332,C$5,Time_Entries!$N$5:$N$332,""))) -> 8 | D9: =IF(COUNTIFS(Lists!$N$5:$N$7,$A9,Lists!$O$5:$O$7,D$5)>0,"LEAVE",IF(SUMIFS(Time_Entries!$J$5:$J$332,Time_Entries!$B$5:$B$332,$A9,Time_Entries!$E$5:$E$332,D$5,Time_Entries!$N$5:$N$332,"")=0,"MISSING",SUMIFS(Time_Entries!$J$5:$J$332,Time_Entries!$B$5:$B$332,$A9,Time_Entries!$E$5:$E$332,D$5,Time_Entries!$N$5:$N$332,""))) -> 8 | E9: =IF(COUNTIFS(Lists!$N$5:$N$7,$A9,Lists!$O$5:$O$7,E$5)>0,"LEAVE",IF(SUMIFS(Time_Entries!$J$5:$J$332,Time_Entries!$B$5:$B$332,$A9,Time_Entries!$E$5:$E$332,E$5,Time_Entries!$N$5:$N$332,"")=0,"MISSING",SUMIFS(Time_Entries!$J$5:$J$332,Time_Entries!$B$5:$B$332,$A9,Time_Entries!$E$5:$E$332,E$5,Time_Entries!$N$5:$N$332,""))) -> 8 | F9: =IF(COUNTIFS(Lists!$N$5:$N$7,$A9,Lists!$O$5:$O$7,F$5)>0,"LEAVE",IF(SUMIFS(Time_Entries!$J$5:$J$332,Time_Entries!$B$5:$B$332,$A9,Time_Entries!$E$5:$E$332,F$5,Time_Entries!$N$5:$N$332,"")=0,"MISSING",SUMIFS(Time_Entries!$J$5:$J$332,Time_Entries!$B$5:$B$332,$A9,Time_Entries!$E$5:$E$332,F$5,Time_Entries!$N$5:$N$332,""))) -> 8 | G9: =IF(COUNTIFS(Lists!$N$5:$N$7,$A9,Lists!$O$5:$O$7,G$5)>0,"LEAVE",IF(SUMIFS(Time_Entries!$J$5:$J$332,Time_Entries!$B$5:$B$332,$A9,Time_Entries!$E$5:$E$332,G$5,Time_Entries!$N$5:$N$332,"")=0,"MISSING",SUMIFS(Time_Entries!$J$5:$J$332,Time_Entries!$B$5:$B$332,$A9,Time_Entries!$E$5:$E$332,G$5,Time_Entries!$N$5:$N$332,""))) -> 8 | H9: =IF(COUNTIFS(Lists!$N$5:$N$7,$A9,Lists!$O$5:$O$7,H$5)>0,"LEAVE",IF(SUMIFS(Time_Entries!$J$5:$J$332,Time_Entries!$B$5:$B$332,$A9,Time_Entries!$E$5:$E$332,H$5,Time_Entries!$N$5:$N$332,"")=0,"MISSING",SUMIFS(Time_Entries!$J$5:$J$332,Time_Entries!$B$5:$B$332,$A9,Time_Entries!$E$5:$E$332,H$5,Time_Entries!$N$5:$N$332,""))) -> 8 | I9: =IF(COUNTIFS(Lists!$N$5:$N$7,$A9,Lists!$O$5:$O$7,I$5)>0,"LEAVE",IF(SUMIFS(Time_Entries!$J$5:$J$332,Time_Entries!$B$5:$B$332,$A9,Time_Entries!$E$5:$E$332,I$5,Time_Entries!$N$5:$N$332,"")=0,"MISSING",SUMIFS(Time_Entries!$J$5:$J$332,Time_Entries!$B$5:$B$332,$A9,Time_Entries!$E$5:$E$332,I$5,Time_Entries!$N$5:$N$332,""))) -> 8 | J9: =IF(COUNTIFS(Lists!$N$5:$N$7,$A9,Lists!$O$5:$O$7,J$5)>0,"LEAVE",IF(SUMIFS(Time_Entries!$J$5:$J$332,Time_Entries!$B$5:$B$332,$A9,Time_Entries!$E$5:$E$332,J$5,Time_Entries!$N$5:$N$332,"")=0,"MISSING",SUMIFS(Time_Entries!$J$5:$J$332,Time_Entries!$B$5:$B$332,$A9,Time_Entries!$E$5:$E$332,J$5,Time_Entries!$N$5:$N$332,""))) -> 8 | ... L9: =IF(COUNTIFS(Lists!$N$5:$N$7,$A9,Lists!$O$5:$O$7,L$5)>0,"LEAVE",IF(SUMIFS(Time_Entries!$J$5:$J$332,Time_Entries!$B$5:$B$332,$A9,Time_Entries!$E$5:$E$332,L$5,Time_Entries!$N$5:$N$332,"")=0,"MISSING",SUMIFS(Time_Entries!$J$5:$J$332,Time_Entries!$B$5:$B$332,$A9,Time_Entries!$E$5:$E$332,L$5,Time_Entries!$N$5:$N$332,""))) -> 8 | M9: =SUM(C9:L9) -> 80 | N9: =8*(10-COUNTIF(C9:L9,"LEAVE")) -> 80 | O9: =M9-N9 -> 0
A10: E005 | B10: =Lists!B9 -> Riley Easton | C10: =IF(COUNTIFS(Lists!$N$5:$N$7,$A10,Lists!$O$5:$O$7,C$5)>0,"LEAVE",IF(SUMIFS(Time_Entries!$J$5:$J$332,Time_Entries!$B$5:$B$332,$A10,Time_Entries!$E$5:$E$332,C$5,Time_Entries!$N$5:$N$332,"")=0,"MISSING",SUMIFS(Time_Entries!$J$5:$J$332,Time_Entries!$B$5:$B$332,$A10,Time_Entries!$E$5:$E$332,C$5,Time_Entries!$N$5:$N$332,""))) -> 8 | D10: =IF(COUNTIFS(Lists!$N$5:$N$7,$A10,Lists!$O$5:$O$7,D$5)>0,"LEAVE",IF(SUMIFS(Time_Entries!$J$5:$J$332,Time_Entries!$B$5:$B$332,$A10,Time_Entries!$E$5:$E$332,D$5,Time_Entries!$N$5:$N$332,"")=0,"MISSING",SUMIFS(Time_Entries!$J$5:$J$332,Time_Entries!$B$5:$B$332,$A10,Time_Entries!$E$5:$E$332,D$5,Time_Entries!$N$5:$N$332,""))) -> 8 | E10: =IF(COUNTIFS(Lists!$N$5:$N$7,$A10,Lists!$O$5:$O$7,E$5)>0,"LEAVE",IF(SUMIFS(Time_Entries!$J$5:$J$332,Time_Entries!$B$5:$B$332,$A10,Time_Entries!$E$5:$E$332,E$5,Time_Entries!$N$5:$N$332,"")=0,"MISSING",SUMIFS(Time_Entries!$J$5:$J$332,Time_Entries!$B$5:$B$332,$A10,Time_Entries!$E$5:$E$332,E$5,Time_Entries!$N$5:$N$332,""))) -> LEAVE | F10: =IF(COUNTIFS(Lists!$N$5:$N$7,$A10,Lists!$O$5:$O$7,F$5)>0,"LEAVE",IF(SUMIFS(Time_Entries!$J$5:$J$332,Time_Entries!$B$5:$B$332,$A10,Time_Entries!$E$5:$E$332,F$5,Time_Entries!$N$5:$N$332,"")=0,"MISSING",SUMIFS(Time_Entries!$J$5:$J$332,Time_Entries!$B$5:$B$332,$A10,Time_Entries!$E$5:$E$332,F$5,Time_Entries!$N$5:$N$332,""))) -> 8 | G10: =IF(COUNTIFS(Lists!$N$5:$N$7,$A10,Lists!$O$5:$O$7,G$5)>0,"LEAVE",IF(SUMIFS(Time_Entries!$J$5:$J$332,Time_Entries!$B$5:$B$332,$A10,Time_Entries!$E$5:$E$332,G$5,Time_Entries!$N$5:$N$332,"")=0,"MISSING",SUMIFS(Time_Entries!$J$5:$J$332,Time_Entries!$B$5:$B$332,$A10,Time_Entries!$E$5:$E$332,G$5,Time_Entries!$N$5:$N$332,""))) -> 8 | H10: =IF(COUNTIFS(Lists!$N$5:$N$7,$A10,Lists!$O$5:$O$7,H$5)>0,"LEAVE",IF(SUMIFS(Time_Entries!$J$5:$J$332,Time_Entries!$B$5:$B$332,$A10,Time_Entries!$E$5:$E$332,H$5,Time_Entries!$N$5:$N$332,"")=0,"MISSING",SUMIFS(Time_Entries!$J$5:$J$332,Time_Entries!$B$5:$B$332,$A10,Time_Entries!$E$5:$E$332,H$5,Time_Entries!$N$5:$N$332,""))) -> 8 | I10: =IF(COUNTIFS(Lists!$N$5:$N$7,$A10,Lists!$O$5:$O$7,I$5)>0,"LEAVE",IF(SUMIFS(Time_Entries!$J$5:$J$332,Time_Entries!$B$5:$B$332,$A10,Time_Entries!$E$5:$E$332,I$5,Time_Entries!$N$5:$N$332,"")=0,"MISSING",SUMIFS(Time_Entries!$J$5:$J$332,Time_Entries!$B$5:$B$332,$A10,Time_Entries!$E$5:$E$332,I$5,Time_Entries!$N$5:$N$332,""))) -> 8 | J10: =IF(COUNTIFS(Lists!$N$5:$N$7,$A10,Lists!$O$5:$O$7,J$5)>0,"LEAVE",IF(SUMIFS(Time_Entries!$J$5:$J$332,Time_Entries!$B$5:$B$332,$A10,Time_Entries!$E$5:$E$332,J$5,Time_Entries!$N$5:$N$332,"")=0,"MISSING",SUMIFS(Time_Entries!$J$5:$J$332,Time_Entries!$B$5:$B$332,$A10,Time_Entries!$E$5:$E$332,J$5,Time_Entries!$N$5:$N$332,""))) -> 8 | ... L10: =IF(COUNTIFS(Lists!$N$5:$N$7,$A10,Lists!$O$5:$O$7,L$5)>0,"LEAVE",IF(SUMIFS(Time_Entries!$J$5:$J$332,Time_Entries!$B$5:$B$332,$A10,Time_Entries!$E$5:$E$332,L$5,Time_Entries!$N$5:$N$332,"")=0,"MISSING",SUMIFS(Time_Entries!$J$5:$J$332,Time_Entries!$B$5:$B$332,$A10,Time_Entries!$E$5:$E$332,L$5,Time_Entries!$N$5:$N$332,""))) -> 8 | M10: =SUM(C10:L10) -> 72 | N10: =8*(10-COUNTIF(C10:L10,"LEAVE")) -> 72 | O10: =M10-N10 -> 0
A11: E006 | B11: =Lists!B10 -> Casey Fenwick | C11: =IF(COUNTIFS(Lists!$N$5:$N$7,$A11,Lists!$O$5:$O$7,C$5)>0,"LEAVE",IF(SUMIFS(Time_Entries!$J$5:$J$332,Time_Entries!$B$5:$B$332,$A11,Time_Entries!$E$5:$E$332,C$5,Time_Entries!$N$5:$N$332,"")=0,"MISSING",SUMIFS(Time_Entries!$J$5:$J$332,Time_Entries!$B$5:$B$332,$A11,Time_Entries!$E$5:$E$332,C$5,Time_Entries!$N$5:$N$332,""))) -> 8 | D11: =IF(COUNTIFS(Lists!$N$5:$N$7,$A11,Lists!$O$5:$O$7,D$5)>0,"LEAVE",IF(SUMIFS(Time_Entries!$J$5:$J$332,Time_Entries!$B$5:$B$332,$A11,Time_Entries!$E$5:$E$332,D$5,Time_Entries!$N$5:$N$332,"")=0,"MISSING",SUMIFS(Time_Entries!$J$5:$J$332,Time_Entries!$B$5:$B$332,$A11,Time_Entries!$E$5:$E$332,D$5,Time_Entries!$N$5:$N$332,""))) -> 8 | E11: =IF(COUNTIFS(Lists!$N$5:$N$7,$A11,Lists!$O$5:$O$7,E$5)>0,"LEAVE",IF(SUMIFS(Time_Entries!$J$5:$J$332,Time_Entries!$B$5:$B$332,$A11,Time_Entries!$E$5:$E$332,E$5,Time_Entries!$N$5:$N$332,"")=0,"MISSING",SUMIFS(Time_Entries!$J$5:$J$332,Time_Entries!$B$5:$B$332,$A11,Time_Entries!$E$5:$E$332,E$5,Time_Entries!$N$5:$N$332,""))) -> 8 | F11: =IF(COUNTIFS(Lists!$N$5:$N$7,$A11,Lists!$O$5:$O$7,F$5)>0,"LEAVE",IF(SUMIFS(Time_Entries!$J$5:$J$332,Time_Entries!$B$5:$B$332,$A11,Time_Entries!$E$5:$E$332,F$5,Time_Entries!$N$5:$N$332,"")=0,"MISSING",SUMIFS(Time_Entries!$J$5:$J$332,Time_Entries!$B$5:$B$332,$A11,Time_Entries!$E$5:$E$332,F$5,Time_Entries!$N$5:$N$332,""))) -> 8 | G11: =IF(COUNTIFS(Lists!$N$5:$N$7,$A11,Lists!$O$5:$O$7,G$5)>0,"LEAVE",IF(SUMIFS(Time_Entries!$J$5:$J$332,Time_Entries!$B$5:$B$332,$A11,Time_Entries!$E$5:$E$332,G$5,Time_Entries!$N$5:$N$332,"")=0,"MISSING",SUMIFS(Time_Entries!$J$5:$J$332,Time_Entries!$B$5:$B$332,$A11,Time_Entries!$E$5:$E$332,G$5,Time_Entries!$N$5:$N$332,""))) -> 8 | H11: =IF(COUNTIFS(Lists!$N$5:$N$7,$A11,Lists!$O$5:$O$7,H$5)>0,"LEAVE",IF(SUMIFS(Time_Entries!$J$5:$J$332,Time_Entries!$B$5:$B$332,$A11,Time_Entries!$E$5:$E$332,H$5,Time_Entries!$N$5:$N$332,"")=0,"MISSING",SUMIFS(Time_Entries!$J$5:$J$332,Time_Entries!$B$5:$B$332,$A11,Time_Entries!$E$5:$E$332,H$5,Time_Entries!$N$5:$N$332,""))) -> 8 | I11: =IF(COUNTIFS(Lists!$N$5:$N$7,$A11,Lists!$O$5:$O$7,I$5)>0,"LEAVE",IF(SUMIFS(Time_Entries!$J$5:$J$332,Time_Entries!$B$5:$B$332,$A11,Time_Entries!$E$5:$E$332,I$5,Time_Entries!$N$5:$N$332,"")=0,"MISSING",SUMIFS(Time_Entries!$J$5:$J$332,Time_Entries!$B$5:$B$332,$A11,Time_Entries!$E$5:$E$332,I$5,Time_Entries!$N$5:$N$332,""))) -> 8 | J11: =IF(COUNTIFS(Lists!$N$5:$N$7,$A11,Lists!$O$5:$O$7,J$5)>0,"LEAVE",IF(SUMIFS(Time_Entries!$J$5:$J$332,Time_Entries!$B$5:$B$332,$A11,Time_Entries!$E$5:$E$332,J$5,Time_Entries!$N$5:$N$332,"")=0,"MISSING",SUMIFS(Time_Entries!$J$5:$J$332,Time_Entries!$B$5:$B$332,$A11,Time_Entries!$E$5:$E$332,J$5,Time_Entries!$N$5:$N$332,""))) -> 8 | ... L11: =IF(COUNTIFS(Lists!$N$5:$N$7,$A11,Lists!$O$5:$O$7,L$5)>0,"LEAVE",IF(SUMIFS(Time_Entries!$J$5:$J$332,Time_Entries!$B$5:$B$332,$A11,Time_Entries!$E$5:$E$332,L$5,Time_Entries!$N$5:$N$332,"")=0,"MISSING",SUMIFS(Time_Entries!$J$5:$J$332,Time_Entries!$B$5:$B$332,$A11,Time_Entries!$E$5:$E$332,L$5,Time_Entries!$N$5:$N$332,""))) -> 8 | M11: =SUM(C11:L11) -> 80 | N11: =8*(10-COUNTIF(C11:L11,"LEAVE")) -> 80 | O11: =M11-N11 -> 0
A12: E007 | B12: =Lists!B11 -> Quinn Garrity | C12: =IF(COUNTIFS(Lists!$N$5:$N$7,$A12,Lists!$O$5:$O$7,C$5)>0,"LEAVE",IF(SUMIFS(Time_Entries!$J$5:$J$332,Time_Entries!$B$5:$B$332,$A12,Time_Entries!$E$5:$E$332,C$5,Time_Entries!$N$5:$N$332,"")=0,"MISSING",SUMIFS(Time_Entries!$J$5:$J$332,Time_Entries!$B$5:$B$332,$A12,Time_Entries!$E$5:$E$332,C$5,Time_Entries!$N$5:$N$332,""))) -> 8 | D12: =IF(COUNTIFS(Lists!$N$5:$N$7,$A12,Lists!$O$5:$O$7,D$5)>0,"LEAVE",IF(SUMIFS(Time_Entries!$J$5:$J$332,Time_Entries!$B$5:$B$332,$A12,Time_Entries!$E$5:$E$332,D$5,Time_Entries!$N$5:$N$332,"")=0,"MISSING",SUMIFS(Time_Entries!$J$5:$J$332,Time_Entries!$B$5:$B$332,$A12,Time_Entries!$E$5:$E$332,D$5,Time_Entries!$N$5:$N$332,""))) -> 8 | E12: =IF(COUNTIFS(Lists!$N$5:$N$7,$A12,Lists!$O$5:$O$7,E$5)>0,"LEAVE",IF(SUMIFS(Time_Entries!$J$5:$J$332,Time_Entries!$B$5:$B$332,$A12,Time_Entries!$E$5:$E$332,E$5,Time_Entries!$N$5:$N$332,"")=0,"MISSING",SUMIFS(Time_Entries!$J$5:$J$332,Time_Entries!$B$5:$B$332,$A12,Time_Entries!$E$5:$E$332,E$5,Time_Entries!$N$5:$N$332,""))) -> 8 | F12: =IF(COUNTIFS(Lists!$N$5:$N$7,$A12,Lists!$O$5:$O$7,F$5)>0,"LEAVE",IF(SUMIFS(Time_Entries!$J$5:$J$332,Time_Entries!$B$5:$B$332,$A12,Time_Entries!$E$5:$E$332,F$5,Time_Entries!$N$5:$N$332,"")=0,"MISSING",SUMIFS(Time_Entries!$J$5:$J$332,Time_Entries!$B$5:$B$332,$A12,Time_Entries!$E$5:$E$332,F$5,Time_Entries!$N$5:$N$332,""))) -> 80 | G12: =IF(COUNTIFS(Lists!$N$5:$N$7,$A12,Lists!$O$5:$O$7,G$5)>0,"LEAVE",IF(SUMIFS(Time_Entries!$J$5:$J$332,Time_Entries!$B$5:$B$332,$A12,Time_Entries!$E$5:$E$332,G$5,Time_Entries!$N$5:$N$332,"")=0,"MISSING",SUMIFS(Time_Entries!$J$5:$J$332,Time_Entries!$B$5:$B$332,$A12,Time_Entries!$E$5:$E$332,G$5,Time_Entries!$N$5:$N$332,""))) -> 8 | H12: =IF(COUNTIFS(Lists!$N$5:$N$7,$A12,Lists!$O$5:$O$7,H$5)>0,"LEAVE",IF(SUMIFS(Time_Entries!$J$5:$J$332,Time_Entries!$B$5:$B$332,$A12,Time_Entries!$E$5:$E$332,H$5,Time_Entries!$N$5:$N$332,"")=0,"MISSING",SUMIFS(Time_Entries!$J$5:$J$332,Time_Entries!$B$5:$B$332,$A12,Time_Entries!$E$5:$E$332,H$5,Time_Entries!$N$5:$N$332,""))) -> 8 | I12: =IF(COUNTIFS(Lists!$N$5:$N$7,$A12,Lists!$O$5:$O$7,I$5)>0,"LEAVE",IF(SUMIFS(Time_Entries!$J$5:$J$332,Time_Entries!$B$5:$B$332,$A12,Time_Entries!$E$5:$E$332,I$5,Time_Entries!$N$5:$N$332,"")=0,"MISSING",SUMIFS(Time_Entries!$J$5:$J$332,Time_Entries!$B$5:$B$332,$A12,Time_Entries!$E$5:$E$332,I$5,Time_Entries!$N$5:$N$332,""))) -> 8 | J12: =IF(COUNTIFS(Lists!$N$5:$N$7,$A12,Lists!$O$5:$O$7,J$5)>0,"LEAVE",IF(SUMIFS(Time_Entries!$J$5:$J$332,Time_Entries!$B$5:$B$332,$A12,Time_Entries!$E$5:$E$332,J$5,Time_Entries!$N$5:$N$332,"")=0,"MISSING",SUMIFS(Time_Entries!$J$5:$J$332,Time_Entries!$B$5:$B$332,$A12,Time_Entries!$E$5:$E$332,J$5,Time_Entries!$N$5:$N$332,""))) -> 8 | ... L12: =IF(COUNTIFS(Lists!$N$5:$N$7,$A12,Lists!$O$5:$O$7,L$5)>0,"LEAVE",IF(SUMIFS(Time_Entries!$J$5:$J$332,Time_Entries!$B$5:$B$332,$A12,Time_Entries!$E$5:$E$332,L$5,Time_Entries!$N$5:$N$332,"")=0,"MISSING",SUMIFS(Time_Entries!$J$5:$J$332,Time_Entries!$B$5:$B$332,$A12,Time_Entries!$E$5:$E$332,L$5,Time_Entries!$N$5:$N$332,""))) -> 8 | M12: =SUM(C12:L12) -> 152 | N12: =8*(10-COUNTIF(C12:L12,"LEAVE")) -> 80 | O12: =M12-N12 -> 72
A13: E008 | B13: =Lists!B12 -> Parker Holloway | C13: =IF(COUNTIFS(Lists!$N$5:$N$7,$A13,Lists!$O$5:$O$7,C$5)>0,"LEAVE",IF(SUMIFS(Time_Entries!$J$5:$J$332,Time_Entries!$B$5:$B$332,$A13,Time_Entries!$E$5:$E$332,C$5,Time_Entries!$N$5:$N$332,"")=0,"MISSING",SUMIFS(Time_Entries!$J$5:$J$332,Time_Entries!$B$5:$B$332,$A13,Time_Entries!$E$5:$E$332,C$5,Time_Entries!$N$5:$N$332,""))) -> 8 | D13: =IF(COUNTIFS(Lists!$N$5:$N$7,$A13,Lists!$O$5:$O$7,D$5)>0,"LEAVE",IF(SUMIFS(Time_Entries!$J$5:$J$332,Time_Entries!$B$5:$B$332,$A13,Time_Entries!$E$5:$E$332,D$5,Time_Entries!$N$5:$N$332,"")=0,"MISSING",SUMIFS(Time_Entries!$J$5:$J$332,Time_Entries!$B$5:$B$332,$A13,Time_Entries!$E$5:$E$332,D$5,Time_Entries!$N$5:$N$332,""))) -> 8 | E13: =IF(COUNTIFS(Lists!$N$5:$N$7,$A13,Lists!$O$5:$O$7,E$5)>0,"LEAVE",IF(SUMIFS(Time_Entries!$J$5:$J$332,Time_Entries!$B$5:$B$332,$A13,Time_Entries!$E$5:$E$332,E$5,Time_Entries!$N$5:$N$332,"")=0,"MISSING",SUMIFS(Time_Entries!$J$5:$J$332,Time_Entries!$B$5:$B$332,$A13,Time_Entries!$E$5:$E$332,E$5,Time_Entries!$N$5:$N$332,""))) -> 8 | F13: =IF(COUNTIFS(Lists!$N$5:$N$7,$A13,Lists!$O$5:$O$7,F$5)>0,"LEAVE",IF(SUMIFS(Time_Entries!$J$5:$J$332,Time_Entries!$B$5:$B$332,$A13,Time_Entries!$E$5:$E$332,F$5,Time_Entries!$N$5:$N$332,"")=0,"MISSING",SUMIFS(Time_Entries!$J$5:$J$332,Time_Entries!$B$5:$B$332,$A13,Time_Entries!$E$5:$E$332,F$5,Time_Entries!$N$5:$N$332,""))) -> 8 | G13: =IF(COUNTIFS(Lists!$N$5:$N$7,$A13,Lists!$O$5:$O$7,G$5)>0,"LEAVE",IF(SUMIFS(Time_Entries!$J$5:$J$332,Time_Entries!$B$5:$B$332,$A13,Time_Entries!$E$5:$E$332,G$5,Time_Entries!$N$5:$N$332,"")=0,"MISSING",SUMIFS(Time_Entries!$J$5:$J$332,Time_Entries!$B$5:$B$332,$A13,Time_Entries!$E$5:$E$332,G$5,Time_Entries!$N$5:$N$332,""))) -> 8 | H13: =IF(COUNTIFS(Lists!$N$5:$N$7,$A13,Lists!$O$5:$O$7,H$5)>0,"LEAVE",IF(SUMIFS(Time_Entries!$J$5:$J$332,Time_Entries!$B$5:$B$332,$A13,Time_Entries!$E$5:$E$332,H$5,Time_Entries!$N$5:$N$332,"")=0,"MISSING",SUMIFS(Time_Entries!$J$5:$J$332,Time_Entries!$B$5:$B$332,$A13,Time_Entries!$E$5:$E$332,H$5,Time_Entries!$N$5:$N$332,""))) -> 8 | I13: =IF(COUNTIFS(Lists!$N$5:$N$7,$A13,Lists!$O$5:$O$7,I$5)>0,"LEAVE",IF(SUMIFS(Time_Entries!$J$5:$J$332,Time_Entries!$B$5:$B$332,$A13,Time_Entries!$E$5:$E$332,I$5,Time_Entries!$N$5:$N$332,"")=0,"MISSING",SUMIFS(Time_Entries!$J$5:$J$332,Time_Entries!$B$5:$B$332,$A13,Time_Entries!$E$5:$E$332,I$5,Time_Entries!$N$5:$N$332,""))) -> 8 | J13: =IF(COUNTIFS(Lists!$N$5:$N$7,$A13,Lists!$O$5:$O$7,J$5)>0,"LEAVE",IF(SUMIFS(Time_Entries!$J$5:$J$332,Time_Entries!$B$5:$B$332,$A13,Time_Entries!$E$5:$E$332,J$5,Time_Entries!$N$5:$N$332,"")=0,"MISSING",SUMIFS(Time_Entries!$J$5:$J$332,Time_Entries!$B$5:$B$332,$A13,Time_Entries!$E$5:$E$332,J$5,Time_Entries!$N$5:$N$332,""))) -> 8 | ... L13: =IF(COUNTIFS(Lists!$N$5:$N$7,$A13,Lists!$O$5:$O$7,L$5)>0,"LEAVE",IF(SUMIFS(Time_Entries!$J$5:$J$332,Time_Entries!$B$5:$B$332,$A13,Time_Entries!$E$5:$E$332,L$5,Time_Entries!$N$5:$N$332,"")=0,"MISSING",SUMIFS(Time_Entries!$J$5:$J$332,Time_Entries!$B$5:$B$332,$A13,Time_Entries!$E$5:$E$332,L$5,Time_Entries!$N$5:$N$332,""))) -> 8 | M13: =SUM(C13:L13) -> 80 | N13: =8*(10-COUNTIF(C13:L13,"LEAVE")) -> 80 | O13: =M13-N13 -> 0
A14: E009 | B14: =Lists!B13 -> Rowan Ingram | C14: =IF(COUNTIFS(Lists!$N$5:$N$7,$A14,Lists!$O$5:$O$7,C$5)>0,"LEAVE",IF(SUMIFS(Time_Entries!$J$5:$J$332,Time_Entries!$B$5:$B$332,$A14,Time_Entries!$E$5:$E$332,C$5,Time_Entries!$N$5:$N$332,"")=0,"MISSING",SUMIFS(Time_Entries!$J$5:$J$332,Time_Entries!$B$5:$B$332,$A14,Time_Entries!$E$5:$E$332,C$5,Time_Entries!$N$5:$N$332,""))) -> 8 | D14: =IF(COUNTIFS(Lists!$N$5:$N$7,$A14,Lists!$O$5:$O$7,D$5)>0,"LEAVE",IF(SUMIFS(Time_Entries!$J$5:$J$332,Time_Entries!$B$5:$B$332,$A14,Time_Entries!$E$5:$E$332,D$5,Time_Entries!$N$5:$N$332,"")=0,"MISSING",SUMIFS(Time_Entries!$J$5:$J$332,Time_Entries!$B$5:$B$332,$A14,Time_Entries!$E$5:$E$332,D$5,Time_Entries!$N$5:$N$332,""))) -> 8 | E14: =IF(COUNTIFS(Lists!$N$5:$N$7,$A14,Lists!$O$5:$O$7,E$5)>0,"LEAVE",IF(SUMIFS(Time_Entries!$J$5:$J$332,Time_Entries!$B$5:$B$332,$A14,Time_Entries!$E$5:$E$332,E$5,Time_Entries!$N$5:$N$332,"")=0,"MISSING",SUMIFS(Time_Entries!$J$5:$J$332,Time_Entries!$B$5:$B$332,$A14,Time_Entries!$E$5:$E$332,E$5,Time_Entries!$N$5:$N$332,""))) -> 8 | F14: =IF(COUNTIFS(Lists!$N$5:$N$7,$A14,Lists!$O$5:$O$7,F$5)>0,"LEAVE",IF(SUMIFS(Time_Entries!$J$5:$J$332,Time_Entries!$B$5:$B$332,$A14,Time_Entries!$E$5:$E$332,F$5,Time_Entries!$N$5:$N$332,"")=0,"MISSING",SUMIFS(Time_Entries!$J$5:$J$332,Time_Entries!$B$5:$B$332,$A14,Time_Entries!$E$5:$E$332,F$5,Time_Entries!$N$5:$N$332,""))) -> 8 | G14: =IF(COUNTIFS(Lists!$N$5:$N$7,$A14,Lists!$O$5:$O$7,G$5)>0,"LEAVE",IF(SUMIFS(Time_Entries!$J$5:$J$332,Time_Entries!$B$5:$B$332,$A14,Time_Entries!$E$5:$E$332,G$5,Time_Entries!$N$5:$N$332,"")=0,"MISSING",SUMIFS(Time_Entries!$J$5:$J$332,Time_Entries!$B$5:$B$332,$A14,Time_Entries!$E$5:$E$332,G$5,Time_Entries!$N$5:$N$332,""))) -> MISSING | H14: =IF(COUNTIFS(Lists!$N$5:$N$7,$A14,Lists!$O$5:$O$7,H$5)>0,"LEAVE",IF(SUMIFS(Time_Entries!$J$5:$J$332,Time_Entries!$B$5:$B$332,$A14,Time_Entries!$E$5:$E$332,H$5,Time_Entries!$N$5:$N$332,"")=0,"MISSING",SUMIFS(Time_Entries!$J$5:$J$332,Time_Entries!$B$5:$B$332,$A14,Time_Entries!$E$5:$E$332,H$5,Time_Entries!$N$5:$N$332,""))) -> 8 | I14: =IF(COUNTIFS(Lists!$N$5:$N$7,$A14,Lists!$O$5:$O$7,I$5)>0,"LEAVE",IF(SUMIFS(Time_Entries!$J$5:$J$332,Time_Entries!$B$5:$B$332,$A14,Time_Entries!$E$5:$E$332,I$5,Time_Entries!$N$5:$N$332,"")=0,"MISSING",SUMIFS(Time_Entries!$J$5:$J$332,Time_Entries!$B$5:$B$332,$A14,Time_Entries!$E$5:$E$332,I$5,Time_Entries!$N$5:$N$332,""))) -> 8 | J14: =IF(COUNTIFS(Lists!$N$5:$N$7,$A14,Lists!$O$5:$O$7,J$5)>0,"LEAVE",IF(SUMIFS(Time_Entries!$J$5:$J$332,Time_Entries!$B$5:$B$332,$A14,Time_Entries!$E$5:$E$332,J$5,Time_Entries!$N$5:$N$332,"")=0,"MISSING",SUMIFS(Time_Entries!$J$5:$J$332,Time_Entries!$B$5:$B$332,$A14,Time_Entries!$E$5:$E$332,J$5,Time_Entries!$N$5:$N$332,""))) -> 8 | ... L14: =IF(COUNTIFS(Lists!$N$5:$N$7,$A14,Lists!$O$5:$O$7,L$5)>0,"LEAVE",IF(SUMIFS(Time_Entries!$J$5:$J$332,Time_Entries!$B$5:$B$332,$A14,Time_Entries!$E$5:$E$332,L$5,Time_Entries!$N$5:$N$332,"")=0,"MISSING",SUMIFS(Time_Entries!$J$5:$J$332,Time_Entries!$B$5:$B$332,$A14,Time_Entries!$E$5:$E$332,L$5,Time_Entries!$N$5:$N$332,""))) -> 8 | M14: =SUM(C14:L14) -> 72 | N14: =8*(10-COUNTIF(C14:L14,"LEAVE")) -> 80 | O14: =M14-N14 -> -8
A15: E010 | B15: =Lists!B14 -> Sage Jarvis | C15: =IF(COUNTIFS(Lists!$N$5:$N$7,$A15,Lists!$O$5:$O$7,C$5)>0,"LEAVE",IF(SUMIFS(Time_Entries!$J$5:$J$332,Time_Entries!$B$5:$B$332,$A15,Time_Entries!$E$5:$E$332,C$5,Time_Entries!$N$5:$N$332,"")=0,"MISSING",SUMIFS(Time_Entries!$J$5:$J$332,Time_Entries!$B$5:$B$332,$A15,Time_Entries!$E$5:$E$332,C$5,Time_Entries!$N$5:$N$332,""))) -> 8 | D15: =IF(COUNTIFS(Lists!$N$5:$N$7,$A15,Lists!$O$5:$O$7,D$5)>0,"LEAVE",IF(SUMIFS(Time_Entries!$J$5:$J$332,Time_Entries!$B$5:$B$332,$A15,Time_Entries!$E$5:$E$332,D$5,Time_Entries!$N$5:$N$332,"")=0,"MISSING",SUMIFS(Time_Entries!$J$5:$J$332,Time_Entries!$B$5:$B$332,$A15,Time_Entries!$E$5:$E$332,D$5,Time_Entries!$N$5:$N$332,""))) -> 8 | E15: =IF(COUNTIFS(Lists!$N$5:$N$7,$A15,Lists!$O$5:$O$7,E$5)>0,"LEAVE",IF(SUMIFS(Time_Entries!$J$5:$J$332,Time_Entries!$B$5:$B$332,$A15,Time_Entries!$E$5:$E$332,E$5,Time_Entries!$N$5:$N$332,"")=0,"MISSING",SUMIFS(Time_Entries!$J$5:$J$332,Time_Entries!$B$5:$B$332,$A15,Time_Entries!$E$5:$E$332,E$5,Time_Entries!$N$5:$N$332,""))) -> 8 | F15: =IF(COUNTIFS(Lists!$N$5:$N$7,$A15,Lists!$O$5:$O$7,F$5)>0,"LEAVE",IF(SUMIFS(Time_Entries!$J$5:$J$332,Time_Entries!$B$5:$B$332,$A15,Time_Entries!$E$5:$E$332,F$5,Time_Entries!$N$5:$N$332,"")=0,"MISSING",SUMIFS(Time_Entries!$J$5:$J$332,Time_Entries!$B$5:$B$332,$A15,Time_Entries!$E$5:$E$332,F$5,Time_Entries!$N$5:$N$332,""))) -> 8 | G15: =IF(COUNTIFS(Lists!$N$5:$N$7,$A15,Lists!$O$5:$O$7,G$5)>0,"LEAVE",IF(SUMIFS(Time_Entries!$J$5:$J$332,Time_Entries!$B$5:$B$332,$A15,Time_Entries!$E$5:$E$332,G$5,Time_Entries!$N$5:$N$332,"")=0,"MISSING",SUMIFS(Time_Entries!$J$5:$J$332,Time_Entries!$B$5:$B$332,$A15,Time_Entries!$E$5:$E$332,G$5,Time_Entries!$N$5:$N$332,""))) -> 8 | H15: =IF(COUNTIFS(Lists!$N$5:$N$7,$A15,Lists!$O$5:$O$7,H$5)>0,"LEAVE",IF(SUMIFS(Time_Entries!$J$5:$J$332,Time_Entries!$B$5:$B$332,$A15,Time_Entries!$E$5:$E$332,H$5,Time_Entries!$N$5:$N$332,"")=0,"MISSING",SUMIFS(Time_Entries!$J$5:$J$332,Time_Entries!$B$5:$B$332,$A15,Time_Entries!$E$5:$E$332,H$5,Time_Entries!$N$5:$N$332,""))) -> 8 | I15: =IF(COUNTIFS(Lists!$N$5:$N$7,$A15,Lists!$O$5:$O$7,I$5)>0,"LEAVE",IF(SUMIFS(Time_Entries!$J$5:$J$332,Time_Entries!$B$5:$B$332,$A15,Time_Entries!$E$5:$E$332,I$5,Time_Entries!$N$5:$N$332,"")=0,"MISSING",SUMIFS(Time_Entries!$J$5:$J$332,Time_Entries!$B$5:$B$332,$A15,Time_Entries!$E$5:$E$332,I$5,Time_Entries!$N$5:$N$332,""))) -> 8 | J15: =IF(COUNTIFS(Lists!$N$5:$N$7,$A15,Lists!$O$5:$O$7,J$5)>0,"LEAVE",IF(SUMIFS(Time_Entries!$J$5:$J$332,Time_Entries!$B$5:$B$332,$A15,Time_Entries!$E$5:$E$332,J$5,Time_Entries!$N$5:$N$332,"")=0,"MISSING",SUMIFS(Time_Entries!$J$5:$J$332,Time_Entries!$B$5:$B$332,$A15,Time_Entries!$E$5:$E$332,J$5,Time_Entries!$N$5:$N$332,""))) -> 8 | ... L15: =IF(COUNTIFS(Lists!$N$5:$N$7,$A15,Lists!$O$5:$O$7,L$5)>0,"LEAVE",IF(SUMIFS(Time_Entries!$J$5:$J$332,Time_Entries!$B$5:$B$332,$A15,Time_Entries!$E$5:$E$332,L$5,Time_Entries!$N$5:$N$332,"")=0,"MISSING",SUMIFS(Time_Entries!$J$5:$J$332,Time_Entries!$B$5:$B$332,$A15,Time_Entries!$E$5:$E$332,L$5,Time_Entries!$N$5:$N$332,""))) -> 8 | M15: =SUM(C15:L15) -> 80 | N15: =8*(10-COUNTIF(C15:L15,"LEAVE")) -> 80 | O15: =M15-N15 -> 0
A16: E011 | B16: =Lists!B15 -> Devon Kessler | C16: =IF(COUNTIFS(Lists!$N$5:$N$7,$A16,Lists!$O$5:$O$7,C$5)>0,"LEAVE",IF(SUMIFS(Time_Entries!$J$5:$J$332,Time_Entries!$B$5:$B$332,$A16,Time_Entries!$E$5:$E$332,C$5,Time_Entries!$N$5:$N$332,"")=0,"MISSING",SUMIFS(Time_Entries!$J$5:$J$332,Time_Entries!$B$5:$B$332,$A16,Time_Entries!$E$5:$E$332,C$5,Time_Entries!$N$5:$N$332,""))) -> 8 | D16: =IF(COUNTIFS(Lists!$N$5:$N$7,$A16,Lists!$O$5:$O$7,D$5)>0,"LEAVE",IF(SUMIFS(Time_Entries!$J$5:$J$332,Time_Entries!$B$5:$B$332,$A16,Time_Entries!$E$5:$E$332,D$5,Time_Entries!$N$5:$N$332,"")=0,"MISSING",SUMIFS(Time_Entries!$J$5:$J$332,Time_Entries!$B$5:$B$332,$A16,Time_Entries!$E$5:$E$332,D$5,Time_Entries!$N$5:$N$332,""))) -> 8 | E16: =IF(COUNTIFS(Lists!$N$5:$N$7,$A16,Lists!$O$5:$O$7,E$5)>0,"LEAVE",IF(SUMIFS(Time_Entries!$J$5:$J$332,Time_Entries!$B$5:$B$332,$A16,Time_Entries!$E$5:$E$332,E$5,Time_Entries!$N$5:$N$332,"")=0,"MISSING",SUMIFS(Time_Entries!$J$5:$J$332,Time_Entries!$B$5:$B$332,$A16,Time_Entries!$E$5:$E$332,E$5,Time_Entries!$N$5:$N$332,""))) -> 8 | F16: =IF(COUNTIFS(Lists!$N$5:$N$7,$A16,Lists!$O$5:$O$7,F$5)>0,"LEAVE",IF(SUMIFS(Time_Entries!$J$5:$J$332,Time_Entries!$B$5:$B$332,$A16,Time_Entries!$E$5:$E$332,F$5,Time_Entries!$N$5:$N$332,"")=0,"MISSING",SUMIFS(Time_Entries!$J$5:$J$332,Time_Entries!$B$5:$B$332,$A16,Time_Entries!$E$5:$E$332,F$5,Time_Entries!$N$5:$N$332,""))) -> 8 | G16: =IF(COUNTIFS(Lists!$N$5:$N$7,$A16,Lists!$O$5:$O$7,G$5)>0,"LEAVE",IF(SUMIFS(Time_Entries!$J$5:$J$332,Time_Entries!$B$5:$B$332,$A16,Time_Entries!$E$5:$E$332,G$5,Time_Entries!$N$5:$N$332,"")=0,"MISSING",SUMIFS(Time_Entries!$J$5:$J$332,Time_Entries!$B$5:$B$332,$A16,Time_Entries!$E$5:$E$332,G$5,Time_Entries!$N$5:$N$332,""))) -> 8 | H16: =IF(COUNTIFS(Lists!$N$5:$N$7,$A16,Lists!$O$5:$O$7,H$5)>0,"LEAVE",IF(SUMIFS(Time_Entries!$J$5:$J$332,Time_Entries!$B$5:$B$332,$A16,Time_Entries!$E$5:$E$332,H$5,Time_Entries!$N$5:$N$332,"")=0,"MISSING",SUMIFS(Time_Entries!$J$5:$J$332,Time_Entries!$B$5:$B$332,$A16,Time_Entries!$E$5:$E$332,H$5,Time_Entries!$N$5:$N$332,""))) -> 8 | I16: =IF(COUNTIFS(Lists!$N$5:$N$7,$A16,Lists!$O$5:$O$7,I$5)>0,"LEAVE",IF(SUMIFS(Time_Entries!$J$5:$J$332,Time_Entries!$B$5:$B$332,$A16,Time_Entries!$E$5:$E$332,I$5,Time_Entries!$N$5:$N$332,"")=0,"MISSING",SUMIFS(Time_Entries!$J$5:$J$332,Time_Entries!$B$5:$B$332,$A16,Time_Entries!$E$5:$E$332,I$5,Time_Entries!$N$5:$N$332,""))) -> MISSING | J16: =IF(COUNTIFS(Lists!$N$5:$N$7,$A16,Lists!$O$5:$O$7,J$5)>0,"LEAVE",IF(SUMIFS(Time_Entries!$J$5:$J$332,Time_Entries!$B$5:$B$332,$A16,Time_Entries!$E$5:$E$332,J$5,Time_Entries!$N$5:$N$332,"")=0,"MISSING",SUMIFS(Time_Entries!$J$5:$J$332,Time_Entries!$B$5:$B$332,$A16,Time_Entries!$E$5:$E$332,J$5,Time_Entries!$N$5:$N$332,""))) -> 8 | ... L16: =IF(COUNTIFS(Lists!$N$5:$N$7,$A16,Lists!$O$5:$O$7,L$5)>0,"LEAVE",IF(SUMIFS(Time_Entries!$J$5:$J$332,Time_Entries!$B$5:$B$332,$A16,Time_Entries!$E$5:$E$332,L$5,Time_Entries!$N$5:$N$332,"")=0,"MISSING",SUMIFS(Time_Entries!$J$5:$J$332,Time_Entries!$B$5:$B$332,$A16,Time_Entries!$E$5:$E$332,L$5,Time_Entries!$N$5:$N$332,""))) -> 8 | M16: =SUM(C16:L16) -> 72 | N16: =8*(10-COUNTIF(C16:L16,"LEAVE")) -> 80 | O16: =M16-N16 -> -8
